Workbook

Sheet 秘宝大作战
D1: 合服调整 | E1: 山国 | F1: 0 | G1: 泽国 | H1: -1 | I1: 龙国 | J1: -1 | K1: 羽国 | L1: -1 | M1: 哈帕迪 | N1: -4
A2: 默认全勤 | B2: 开服日期 | C2: 45930 | D2: 累计能量 | E2: 正常五层奖励 | F2: 跳期修正后五层奖励 | G2: 奖励兑换 | H2: 累计需要能量 | I2: 能量情况 | J2: 本期购买能量 | K2: 累计购买能量 | L2: 是否足够 | M2: 推荐0氪兑换 | N2: 零氪剩余能量 | Q2: 左侧是作者的记录，黄色格子根据个人情况修改
A3: 山国 | B3: 第1期 | C3: =C2+7 -> 45937 | D3: =数据计算表!J2 -> 2250 | E3: =数据计算表!M2 -> 自选奇迹遗物·山 | F3: =数据计算表!N2 -> 自选奇迹遗物·山 | G3: 换五层 | H3: =HLOOKUP(G3,数据计算表!$A$3:$H$4,2,FALSE) -> 3240 | I3: =IF(D3-H3>=0,"剩余"&D3-H3,"需要"&D3-H3) -> 需要-990 | J3: 2920 | K3: =J3 -> 2920 | L3: =IF(K3>(H3-D3),"√","×") -> √ | M3: 不换 | N3: =D3-IF(M3="换",3240,0) -> 2250
A4: 泽国 | B4: 第2期 | C4: =C3+7 -> 45944 | D4: =数据计算表!J3 -> 4500 | E4: =数据计算表!M3 -> 幸运神像 | F4: =数据计算表!N3 -> 幸运神像 | G4: 换五层 | H4: =HLOOKUP(G4,数据计算表!$A$3:$H$4,2,FALSE)+H3 -> 6480 | I4: =IF(D4-H4>=0,"剩余"&D4-H4,"需要"&D4-H4) -> 需要-1980 | J4: 1720 | K4: =K3+J4 -> 4640 | L4: =IF(K4>(H4-D4),"√","×") -> √ | M4: 换 | N4: =N3+2250-IF(M4="换",3240,0) -> 1260
B5: 第3期 | C5: =C4+7 -> 45951 | D5: =数据计算表!J4 -> 6750 | E5: =数据计算表!M4 -> 3阶技能碎片*180 | F5: =数据计算表!N4 -> 3阶技能碎片*180 | G5: 换五层 | H5: =HLOOKUP(G5,数据计算表!$A$3:$H$4,2,FALSE)+H4 -> 9720 | I5: =IF(D5-H5>=0,"剩余"&D5-H5,"需要"&D5-H5) -> 需要-2970 | J5: 720 | K5: =K4+J5 -> 5360 | L5: =IF(K5>(H5-D5),"√","×") -> √ | M5: 换 | N5: =N4+2250-IF(M5="换",3240,0) -> 270 | Q5: 零氪党换的期数换到5级，不换的期数一个都不换
B6: 第4期 | C6: =C5+7 -> 45958 | D6: =数据计算表!J5 -> 9000 | E6: =数据计算表!M5 -> 原初宝石 | F6: =数据计算表!N5 -> 原初宝石 | G6: 换五层 | H6: =HLOOKUP(G6,数据计算表!$A$3:$H$4,2,FALSE)+H5 -> 12960 | I6: =IF(D6-H6>=0,"剩余"&D6-H6,"需要"&D6-H6) -> 需要-3960 | J6: 1720 | K6: =K5+J6 -> 7080 | L6: =IF(K6>(H6-D6),"√","×") -> √ | M6: 不换 | N6: =N5+2250-IF(M6="换",3240,0) -> 2520
B7: 第5期 | C7: =C6+7 -> 45965 | D7: =数据计算表!J6 -> 11250 | E7: =数据计算表!M6 -> 自选奇迹遗物·泽 | F7: =数据计算表!N6 -> 自选奇迹遗物·泽 | G7: 换两个五层 | H7: =HLOOKUP(G7,数据计算表!$A$3:$H$4,2,FALSE)+H6 -> 17400 | I7: =IF(D7-H7>=0,"剩余"&D7-H7,"需要"&D7-H7) -> 需要-6150 | J7: 720 | K7: =K6+J7 -> 7800 | L7: =IF(K7>(H7-D7),"√","×") -> √ | M7: 不换 | N7: =N6+2250-IF(M7="换",3240,0) -> 4770
B8: 第6期 | C8: =C7+7 -> 45972 | D8: =数据计算表!J7 -> 13500 | E8: =数据计算表!M7 -> 幸运神像 | F8: =数据计算表!N7 -> 幸运神像 | G8: 换五层 | H8: =HLOOKUP(G8,数据计算表!$A$3:$H$4,2,FALSE)+H7 -> 20640 | I8: =IF(D8-H8>=0,"剩余"&D8-H8,"需要"&D8-H8) -> 需要-7140 | J8: 720 | K8: =K7+J8 -> 8520 | L8: =IF(K8>(H8-D8),"√","×") -> √ | M8: 换 | N8: =N7+2250-IF(M8="换",3240,0) -> 3780 | Q8: 秘宝跳期 | R8: 是
A9: 龙国 | B9: 第7期 | C9: =C8+7 -> 45979 | D9: =数据计算表!J8 -> 15750 | E9: =数据计算表!M8 -> 4阶技能碎片*180 | F9: =数据计算表!N8 -> 4阶技能碎片*180 | G9: 换五层 | H9: =HLOOKUP(G9,数据计算表!$A$3:$H$4,2,FALSE)+H8 -> 23880 | I9: =IF(D9-H9>=0,"剩余"&D9-H9,"需要"&D9-H9) -> 需要-8130 | J9: 1720 | K9: =K8+J9 -> 10240 | L9: =IF(K9>(H9-D9),"√","×") -> √ | M9: 换 | N9: =N8+2250-IF(M9="换",3240,0) -> 2790 | Q9: 期数 | R9: 五层奖励
B10: 第8期 | C10: =C9+7 -> 45986 | D10: =数据计算表!J9 -> 18000 | E10: =数据计算表!M9 -> 原初宝石 | F10: =数据计算表!N9 -> 原初宝石 | G10: 换三个五层 | H10: =HLOOKUP(G10,数据计算表!$A$3:$H$4,2,FALSE)+H9 -> 29520 | I10: =IF(D10-H10>=0,"剩余"&D10-H10,"需要"&D10-H10) -> 需要-11520 | J10: 3420 | K10: =K9+J10 -> 13660 | L10: =IF(K10>(H10-D10),"√","×") -> √ | M10: 换 | N10: =N9+2250-IF(M10="换",3240,0) -> 1800 | Q10: 16 | R10: =数据计算表!P3 -> 原初宝石
B11: 第9期 | C11: =C10+7 -> 45993 | D11: =数据计算表!J10 -> 20250 | E11: =数据计算表!M10 -> 自选奇迹遗物·龙I | F11: =数据计算表!N10 -> 自选奇迹遗物·龙I | G11: 换三个五层 | H11: =HLOOKUP(G11,数据计算表!$A$3:$H$4,2,FALSE)+H10 -> 35160 | I11: =IF(D11-H11>=0,"剩余"&D11-H11,"需要"&D11-H11) -> 需要-14910 | J11: 3420 | K11: =K10+J11 -> 17080 | L11: =IF(K11>(H11-D11),"√","×") -> √ | M11: 换 | N11: =N10+2250-IF(M11="换",3240,0) -> 810
B12: 第10期 | C12: =C11+7 -> 46000 | D12: =数据计算表!J11 -> 22350 | E12: =数据计算表!M11 -> 幸运神像 | F12: =数据计算表!N11 -> 幸运神像 | G12: 换两个五层 | H12: =HLOOKUP(G12,数据计算表!$A$3:$H$4,2,FALSE)+H11 -> 39600 | I12: =IF(D12-H12>=0,"剩余"&D12-H12,"需要"&D12-H12) -> 需要-17250 | J12: 1720 | K12: =K11+J12 -> 18800 | L12: =IF(K12>(H12-D12),"√","×") -> √ | M12: 不换 | N12: =N11+2250-IF(M12="换",3240,0) -> 3060 | Q12: 第几期漏做日常 | R12: 10
B13: 第11期 | C13: =C12+7 -> 46007 | D13: =数据计算表!J12 -> 24600 | E13: =数据计算表!M12 -> 4阶技能碎片*180 | F13: =数据计算表!N12 -> 4阶技能碎片*180 | G13: 换五层 | H13: =HLOOKUP(G13,数据计算表!$A$3:$H$4,2,FALSE)+H12 -> 42840 | I13: =IF(D13-H13>=0,"剩余"&D13-H13,"需要"&D13-H13) -> 需要-18240 | J13: 1720 | K13: =K12+J13 -> 20520 | L13: =IF(K13>(H13-D13),"√","×") -> √ | M13: 换 | N13: =N12+2250-IF(M13="换",3240,0) -> 2070 | Q13: 累计漏获得能量 | R13: 150
B14: 第12期 | C14: =C13+7 -> 46014 | D14: =数据计算表!J13 -> 26850 | E14: =数据计算表!M13 -> 原初宝石 | F14: =数据计算表!N13 -> 原初宝石 | G14: 换五层 | H14: =HLOOKUP(G14,数据计算表!$A$3:$H$4,2,FALSE)+H13 -> 46080 | I14: =IF(D14-H14>=0,"剩余"&D14-H14,"需要"&D14-H14) -> 需要-19230 | J14: 1720 | K14: =K13+J14 -> 22240 | L14: =IF(K14>(H14-D14),"√","×") -> √ | M14: 不换 | N14: =N13+2250-IF(M14="换",3240,0) -> 4320 | Q14: 累计跳期补偿能量 | R14: =数据计算表!P4 -> 1000
B15: 第13期 | C15: =C14+7 -> 46021 | D15: =数据计算表!J14 -> 29100 | E15: =数据计算表!M14 -> 自选奇迹遗物·龙II | F15: =数据计算表!N14 -> 自选奇迹遗物·龙II | G15: 换两个五层 | H15: =HLOOKUP(G15,数据计算表!$A$3:$H$4,2,FALSE)+H14 -> 50520 | I15: =IF(D15-H15>=0,"剩余"&D15-H15,"需要"&D15-H15) -> 需要-21420 | J15: 1720 | K15: =K14+J15 -> 23960 | L15: =IF(K15>(H15-D15),"√","×") -> √ | M15: 换 | N15: =N14+2250-IF(M15="换",3240,0) -> 3330
B16: 第14期 | C16: =C15+7 -> 46028 | D16: =数据计算表!J15 -> 31350 | E16: =数据计算表!M15 -> 幸运神像 | F16: =数据计算表!N15 -> 幸运神像 | G16: 换两个五层 | H16: =HLOOKUP(G16,数据计算表!$A$3:$H$4,2,FALSE)+H15 -> 54960 | I16: =IF(D16-H16>=0,"剩余"&D16-H16,"需要"&D16-H16) -> 需要-23610 | J16: 1720 | K16: =K15+J16 -> 25680 | L16: =IF(K16>(H16-D16),"√","×") -> √ | M16: 不换 | N16: =N15+2250-IF(M16="换",3240,0) -> 5580
B17: 第15期 | C17: =C16+7 -> 46035 | D17: =数据计算表!J16 -> 33600 | E17: =数据计算表!M16 -> 4阶技能碎片*180 | F17: =数据计算表!N16 -> 4阶技能碎片*180 | G17: 换两个五层 | H17: =HLOOKUP(G17,数据计算表!$A$3:$H$4,2,FALSE)+H16 -> 59400 | I17: =IF(D17-H17>=0,"剩余"&D17-H17,"需要"&D17-H17) -> 需要-25800 | J17: 1720 | K17: =K16+J17 -> 27400 | L17: =IF(K17>(H17-D17),"√","×") -> √ | M17: 换 | N17: =N16+2250-IF(M17="换",3240,0) -> 4590
B18: 第16期 | C18: =C17+7 -> 46042 | D18: =数据计算表!J17 -> 36850 | E18: =数据计算表!M17 -> 原初宝石 | F18: =数据计算表!N17 -> 自选奇迹遗物·羽I | G18: 换三个五层 | H18: =HLOOKUP(G18,数据计算表!$A$3:$H$4,2,FALSE)+H17 -> 65040 | I18: =IF(D18-H18>=0,"剩余"&D18-H18,"需要"&D18-H18) -> 需要-28190 | J18: 1720 | K18: =K17+J18 -> 29120 | L18: =IF(K18>(H18-D18),"√","×") -> √ | M18: 不换 | N18: =N17+2250-IF(M18="换",3240,0) -> 6840
A19: 羽国 | B19: 第17期 | C19: =C18+7 -> 46049 | D19: =数据计算表!J18 -> 39100 | E19: =数据计算表!M18 -> 自选奇迹遗物·羽I | F19: =数据计算表!N18 -> 原初宝石/贤者之石 | G19: 换两个五层 | H19: =HLOOKUP(G19,数据计算表!$A$3:$H$4,2,FALSE)+H18 -> 69480 | I19: =IF(D19-H19>=0,"剩余"&D19-H19,"需要"&D19-H19) -> 需要-30380 | J19: 3420 | K19: =K18+J19 -> 32540 | L19: =IF(K19>(H19-D19),"√","×") -> √ | M19: 换 | N19: =N18+2250-IF(M19="换",3240,0) -> 5850
B20: 第18期 | C20: =C19+7 -> 46056 | D20: =数据计算表!J19 -> 41350 | E20: =数据计算表!M19 -> 幸运神像/黄金圣木 | F20: =数据计算表!N19 -> 幸运神像/黄金圣木 | G20: 换两个五层 | H20: =HLOOKUP(G20,数据计算表!$A$3:$H$4,2,FALSE)+H19 -> 73920 | I20: =IF(D20-H20>=0,"剩余"&D20-H20,"需要"&D20-H20) -> 需要-32570 | J20: 3420 | K20: =K19+J20 -> 35960 | L20: =IF(K20>(H20-D20),"√","×") -> √ | M20: 换 | N20: =N19+2250-IF(M20="换",3240,0) -> 4860
B21: 第19期 | C21: =C20+7 -> 46063 | D21: =数据计算表!J20 -> 43600 | E21: =数据计算表!M20 -> 5阶技能碎片*180 | F21: =数据计算表!N20 -> 5阶技能碎片*180 | G21: 换三个五层 | H21: =HLOOKUP(G21,数据计算表!$A$3:$H$4,2,FALSE)+H20 -> 79560 | I21: =IF(D21-H21>=0,"剩余"&D21-H21,"需要"&D21-H21) -> 需要-35960 | J21: 3420 | K21: =K20+J21 -> 39380 | L21: =IF(K21>(H21-D21),"√","×") -> √ | M21: 换 | N21: =N20+2250-IF(M21="换",3240,0) -> 3870
B22: 第20期 | C22: =C21+7 -> 46070 | D22: =数据计算表!J21 -> 45850 | E22: =数据计算表!M21 -> 原初宝石/贤者之石 | F22: =数据计算表!N21 -> 原初宝石/贤者之石 | G22: 换两个五层 | H22: =HLOOKUP(G22,数据计算表!$A$3:$H$4,2,FALSE)+H21 -> 84000 | I22: =IF(D22-H22>=0,"剩余"&D22-H22,"需要"&D22-H22) -> 需要-38150 | J22: 1720 | K22: =K21+J22 -> 41100 | L22: =IF(K22>(H22-D22),"√","×") -> √ | M22: 换 | N22: =N21+2250-IF(M22="换",3240,0) -> 2880
B23: 第21期 | C23: =C22+7 -> 46077 | D23: =数据计算表!J22 -> 48100 | E23: =数据计算表!M22 -> 自选奇迹遗物·羽II | F23: =数据计算表!N22 -> 自选奇迹遗物·羽II | G23: 换五层 | H23: =HLOOKUP(G23,数据计算表!$A$3:$H$4,2,FALSE)+H22 -> 87240 | I23: =IF(D23-H23>=0,"剩余"&D23-H23,"需要"&D23-H23) -> 需要-39140 | J23: 720 | K23: =K22+J23 -> 41820 | L23: =IF(K23>(H23-D23),"√","×") -> √ | M23: 换 | N23: =N22+2250-IF(M23="换",3240,0) -> 1890
B24: 第22期 | C24: =C23+7 -> 46084 | D24: =数据计算表!J23 -> 50350 | E24: =数据计算表!M23 -> 幸运神像/黄金圣木 | F24: =数据计算表!N23 -> 幸运神像/黄金圣木 | G24: 不换 | H24: =HLOOKUP(G24,数据计算表!$A$3:$H$4,2,FALSE)+H23 -> 87240 | I24: =IF(D24-H24>=0,"剩余"&D24-H24,"需要"&D24-H24) -> 需要-36890 | J24: 720 | K24: =K23+J24 -> 42540 | L24: =IF(K24>(H24-D24),"√","×") -> √ | M24: 不换 | N24: =N23+2250-IF(M24="换",3240,0) -> 4140
B25: 第23期 | C25: =C24+7 -> 46091 | D25: =数据计算表!J24 -> 52600 | E25: =数据计算表!M24 -> 5阶技能碎片*180 | F25: =数据计算表!N24 -> 5阶技能碎片*180 | G25: 换三个五层 | H25: =HLOOKUP(G25,数据计算表!$A$3:$H$4,2,FALSE)+H24 -> 92880 | I25: =IF(D25-H25>=0,"剩余"&D25-H25,"需要"&D25-H25) -> 需要-40280 | J25: 720 | K25: =K24+J25 -> 43260 | L25: =IF(K25>(H25-D25),"√","×") -> √ | M25: 换 | N25: =N24+2250-IF(M25="换",3240,0) -> 3150
B26: 第24期 | C26: =C25+7 -> 46098 | D26: =数据计算表!J25 -> 54850 | E26: =数据计算表!M25 -> 原初宝石/贤者之石 | F26: =数据计算表!N25 -> 原初宝石/贤者之石 | G26: 不换 | H26: =HLOOKUP(G26,数据计算表!$A$3:$H$4,2,FALSE)+H25 -> 92880 | I26: =IF(D26-H26>=0,"剩余"&D26-H26,"需要"&D26-H26) -> 需要-38030 | J26: 720 | K26: =K25+J26 -> 43980 | L26: =IF(K26>(H26-D26),"√","×") -> √ | M26: 不换 | N26: =N25+2250-IF(M26="换",3240,0) -> 5400
B27: 第25期 | C27: =C26+7 -> 46105 | D27: =数据计算表!J26 -> 57100 | E27: =数据计算表!M26 -> 自选奇迹遗物·羽III | F27: =数据计算表!N26 -> 自选奇迹遗物·羽III | G27: 换三个五层 | H27: =HLOOKUP(G27,数据计算表!$A$3:$H$4,2,FALSE)+H26 -> 98520 | I27: =IF(D27-H27>=0,"剩余"&D27-H27,"需要"&D27-H27) -> 需要-41420 | J27: 720 | K27: =K26+J27 -> 44700 | L27: =IF(K27>(H27-D27),"√","×") -> √ | M27: 换 | N27: =N26+2250-IF(M27="换",3240,0) -> 4410
B28: 第26期 | C28: =C27+7 -> 46112 | D28: =数据计算表!J27 -> 59350 | E28: =数据计算表!M27 -> 幸运神像/黄金圣木 | F28: =数据计算表!N27 -> 幸运神像/黄金圣木 | G28: 不换 | H28: =HLOOKUP(G28,数据计算表!$A$3:$H$4,2,FALSE)+H27 -> 98520 | I28: =IF(D28-H28>=0,"剩余"&D28-H28,"需要"&D28-H28) -> 需要-39170 | J28: 3420 | K28: =K27+J28 -> 48120 | L28: =IF(K28>(H28-D28),"√","×") -> √ | M28: 不换 | N28: =N27+2250-IF(M28="换",3240,0) -> 6660
B29: 第27期 | C29: =C28+7 -> 46119 | D29: =数据计算表!J28 -> 61600 | E29: =数据计算表!M28 -> 5阶技能碎片*180 | F29: =数据计算表!N28 -> 5阶技能碎片*180 | G29: 换三个五层 | H29: =HLOOKUP(G29,数据计算表!$A$3:$H$4,2,FALSE)+H28 -> 104160 | I29: =IF(D29-H29>=0,"剩余"&D29-H29,"需要"&D29-H29) -> 需要-42560 | J29: 3420 | K29: =K28+J29 -> 51540 | L29: =IF(K29>(H29-D29),"√","×") -> √ | M29: 换 | N29: =N28+2250-IF(M29="换",3240,0) -> 5670
B30: 第28期 | C30: =C29+7 -> 46126 | D30: =数据计算表!J29 -> 63850 | E30: =数据计算表!M29 -> 原初宝石/贤者之石 | F30: =数据计算表!N29 -> 原初宝石/贤者之石 | G30: 换两个五层 | H30: =HLOOKUP(G30,数据计算表!$A$3:$H$4,2,FALSE)+H29 -> 108600 | I30: =IF(D30-H30>=0,"剩余"&D30-H30,"需要"&D30-H30) -> 需要-44750 | J30: 720 | K30: =K29+J30 -> 52260 | L30: =IF(K30>(H30-D30),"√","×") -> √ | M30: 不换 | N30: =N29+2250-IF(M30="换",3240,0) -> 7920
B31: 第29期 | C31: =C30+7 -> 46133 | D31: =数据计算表!J30 -> 66100 | E31: =数据计算表!M30 -> 自选奇迹遗物·羽III | F31: =数据计算表!N30 -> 自选奇迹遗物·羽III | G31: 换三个五层 | H31: =HLOOKUP(G31,数据计算表!$A$3:$H$4,2,FALSE)+H30 -> 114240 | I31: =IF(D31-H31>=0,"剩余"&D31-H31,"需要"&D31-H31) -> 需要-48140 | J31: 720 | K31: =K30+J31 -> 52980 | L31: =IF(K31>(H31-D31),"√","×") -> √ | M31: 换 | N31: =N30+2250-IF(M31="换",3240,0) -> 6930
B32: 第30期 | C32: =C31+7 -> 46140 | D32: =数据计算表!J31 -> 68350 | E32: =数据计算表!M31 -> 幸运神像/黄金圣木 | F32: =数据计算表!N31 -> 幸运神像/黄金圣木 | G32: 换五层 | H32: =HLOOKUP(G32,数据计算表!$A$3:$H$4,2,FALSE)+H31 -> 117480 | I32: =IF(D32-H32>=0,"剩余"&D32-H32,"需要"&D32-H32) -> 需要-49130 | J32: 720 | K32: =K31+J32 -> 53700 | L32: =IF(K32>(H32-D32),"√","×") -> √ | M32: 不换 | N32: =N31+2250-IF(M32="换",3240,0) -> 9180
A33: 哈帕迪 | B33: 第31期 | C33: =C32+7 -> 46147 | D33: =数据计算表!J32 -> 70600 | E33: =数据计算表!M32 -> 6阶技能碎片*180 | F33: =数据计算表!N32 -> 6阶技能碎片*180 | G33: 换五层 | H33: =HLOOKUP(G33,数据计算表!$A$3:$H$4,2,FALSE)+H32 -> 120720 | I33: =IF(D33-H33>=0,"剩余"&D33-H33,"需要"&D33-H33) -> 需要-50120 | J33: 720 | K33: =K32+J33 -> 54420 | L33: =IF(K33>(H33-D33),"√","×") -> √ | M33: 换 | N33: =N32+2250-IF(M33="换",3240,0) -> 8190
B34: 第32期 | C34: =C33+7 -> 46154 | D34: =数据计算表!J33 -> 72850 | E34: =数据计算表!M33 -> 原初宝石/贤者之石/秘宝探测仪 | F34: =数据计算表!N33 -> 原初宝石/贤者之石/秘宝探测仪 | G34: 换五层 | H34: =HLOOKUP(G34,数据计算表!$A$3:$H$4,2,FALSE)+H33 -> 123960 | I34: =IF(D34-H34>=0,"剩余"&D34-H34,"需要"&D34-H34) -> 需要-51110 | J34: 720 | K34: =K33+J34 -> 55140 | L34: =IF(K34>(H34-D34),"√","×") -> √ | M34: 换 | N34: =N33+2250-IF(M34="换",3240,0) -> 7200
B35: 第33期 | C35: =C34+7 -> 46161 | D35: =数据计算表!J34 -> 75100 | E35: =数据计算表!M34 -> 自选奇迹遗物·哈I | F35: =数据计算表!N34 -> 自选奇迹遗物·哈I | G35: 换五层 | H35: =HLOOKUP(G35,数据计算表!$A$3:$H$4,2,FALSE)+H34 -> 127200 | I35: =IF(D35-H35>=0,"剩余"&D35-H35,"需要"&D35-H35) -> 需要-52100 | J35: 720 | K35: =K34+J35 -> 55860 | L35: =IF(K35>(H35-D35),"√","×") -> √ | M35: 换 | N35: =N34+2250-IF(M35="换",3240,0) -> 6210
B36: 第34期 | C36: =C35+7 -> 46168 | D36: =数据计算表!J35 -> 77350 | E36: =数据计算表!M35 -> 幸运神像/黄金圣木/无尽沙漏 | F36: =数据计算表!N35 -> 幸运神像/黄金圣木/无尽沙漏 | G36: 不换 | H36: =HLOOKUP(G36,数据计算表!$A$3:$H$4,2,FALSE)+H35 -> 127200 | I36: =IF(D36-H36>=0,"剩余"&D36-H36,"需要"&D36-H36) -> 需要-49850 | J36: 720 | K36: =K35+J36 -> 56580 | L36: =IF(K36>(H36-D36),"√","×") -> √ | M36: 换 | N36: =N35+2250-IF(M36="换",3240,0) -> 5220
B37: 第35期 | C37: =C36+7 -> 46175 | D37: =数据计算表!J36 -> 79600 | E37: =数据计算表!M36 -> 6阶技能碎片*180 | F37: =数据计算表!N36 -> 6阶技能碎片*180 | G37: 换五层 | H37: =HLOOKUP(G37,数据计算表!$A$3:$H$4,2,FALSE)+H36 -> 130440 | I37: =IF(D37-H37>=0,"剩余"&D37-H37,"需要"&D37-H37) -> 需要-50840 | J37: 720 | K37: =K36+J37 -> 57300 | L37: =IF(K37>(H37-D37),"√","×") -> √ | M37: 换 | N37: =N36+2250-IF(M37="换",3240,0) -> 4230
B38: 第36期 | C38: =C37+7 -> 46182 | D38: =数据计算表!J37 -> 81850 | E38: =数据计算表!M37 -> 原初宝石/贤者之石/秘宝探测仪 | F38: =数据计算表!N37 -> 原初宝石/贤者之石/秘宝探测仪 | G38: 换五层 | H38: =HLOOKUP(G38,数据计算表!$A$3:$H$4,2,FALSE)+H37 -> 133680 | I38: =IF(D38-H38>=0,"剩余"&D38-H38,"需要"&D38-H38) -> 需要-51830 | J38: 720 | K38: =K37+J38 -> 58020 | L38: =IF(K38>(H38-D38),"√","×") -> √ | M38: 换 | N38: =N37+2250-IF(M38="换",3240,0) -> 3240
B39: 第37期 | C39: =C38+7 -> 46189 | D39: =数据计算表!J38 -> 84100 | E39: =数据计算表!M38 -> 自选奇迹遗物·哈II | F39: =数据计算表!N38 -> 自选奇迹遗物·哈II | G39: 换五层 | H39: =HLOOKUP(G39,数据计算表!$A$3:$H$4,2,FALSE)+H38 -> 136920 | I39: =IF(D39-H39>=0,"剩余"&D39-H39,"需要"&D39-H39) -> 需要-52820 | J39: 720 | K39: =K38+J39 -> 58740 | L39: =IF(K39>(H39-D39),"√","×") -> √ | M39: 换 | N39: =N38+2250-IF(M39="换",3240,0) -> 2250
B40: 第38期 | C40: =C39+7 -> 46196 | D40: =数据计算表!J39 -> 86350 | E40: =数据计算表!M39 -> 幸运神像/黄金圣木/无尽沙漏 | F40: =数据计算表!N39 -> 幸运神像/黄金圣木/无尽沙漏 | G40: 不换 | H40: =HLOOKUP(G40,数据计算表!$A$3:$H$4,2,FALSE)+H39 -> 136920 | I40: =IF(D40-H40>=0,"剩余"&D40-H40,"需要"&D40-H40) -> 需要-50570 | J40: 720 | K40: =K39+J40 -> 59460 | L40: =IF(K40>(H40-D40),"√","×") -> √ | M40: 不换 | N40: =N39+2250-IF(M40="换",3240,0) -> 4500
...

Sheet 幻兽同调计算器
A1: 当前幻兽品质 | C1: 奇迹 | F1: 对比幻兽品质 | H1: 传说
A2: 当前幻兽同调率 | C2: 1.36 | F2: 对比幻兽同调率 | H2: 1.49
A3: 当前重置后幻兽面板 | B3: 攻击力 | C3: 5.18 | F3: 当前重置后幻兽面板 | G3: 攻击力 | H3: =数据计算表!EJ18 -> 4.2563603
B4: 防御力 | C4: 5.18 | G4: 防御力 | H4: =数据计算表!EJ19 -> 4.2563603
B5: 生命值 | C5: 25.9 | G5: 生命值 | H5: =数据计算表!EJ20 -> 21.281801
B6: 速度 | C6: 4.14 | G6: 速度 | H6: =数据计算表!EJ21 -> 3.4018015
B7: 战力 | C7: =数据计算表!EF22 -> 51.7875 | G7: 战力 | H7: =数据计算表!EK22 -> 42.553332
A8: 幻兽点满能力页数量 | C8: 1 | F8: 幻兽点满能力页数量 | H8: 1
A9: 点满能力页后面板 | B9: 攻击力
B10: 防御力
B11: 生命值
B12: 速度
B13: 战力

Sheet 数据计算表
A1: 一层 | B1: 二层 | C1: 三层 | D1: 四层 | E1: 五层 | J1: 能量 | K1: 期数 | L1: 天数 | M1: 正常序列 | N1: 跳期修正 | O1: 是否跳期 | P1: =秘宝大作战!R8 -> 是 | Q1: 漏做期数 | R1: =秘宝大作战!R12 -> 10 | V1: 星象合约部分 | AE1: 递增 | AF1: 累计 | AG1: 效果 | AH1: 百分比 | AI1: 累计效果 | AK1: 泽国选中原初之星数量 | AL1: 泽国原初档位 | AM1: 副本掉落装备升华率 | AN1: 宝石获取率 | AO1: 副本评价奖励翻倍概率 | AP1: 经验获取加成 | AU1: 泽国 | AW1: 龙国 | AY1: 羽国 | BB1: 经验计算处理区 | BJ1: 钥匙 | BK1: 药水 | BL1: 钻头 | BM1: 水雷 | BN1: 云 | BO1: 锤子 | BS1: 晨星 | BX1: 强化消耗 | BZ1: 装备 | CA1: 粗练石 | CB1: 金币 | CC1: 晨星价值 | CD1: 原初价格 | CE1: 原初体力消耗 | CG1: 技能 | CH1: 历战精华 | CI1: 金币 | CJ1: 晨星价值 | CK1: 原初价格 | CL1: 原初体力消耗 | CN1: 遗物 | CO1: 时之沙 | CP1: 金币 | CQ1: 晨星价值 | CR1: 原初价格 | CS1: 原初体力消耗 | CU1: 幻兽 | CV1: 经验 | CW1: 金币 | CX1: 晨星价值 | CY1: 原初价格 | DD1: 宝石 | DN1: 宝石价格 | DO1: =属性晨星性价比!B2 -> 720 | DQ1: 选择幻兽品质 | DR1: =属性晨星性价比!C17 -> 奇迹 | DS1: 占位 | DT1: =IF(DR1="奇迹",1.2,IF(DR1="传说",1.1,1)) -> 1.2 | ED1: 攻击 | EE1: 防御 | EF1: 生命 | EG1: 速度 | FB1: 伙伴经验需求 | FN1: 碎片率 | FO1: 整装率 | FQ1: 蓝色遗物属性类别 | FR1: =属性晨星性价比!R6 -> 攻击 | FT1: 0星 | FU1: 1 | FW1: 攻击 | FX1: 2.5
A2: 240 | B2: 400 | C2: 600 | D2: 800 | E2: 1200 | J2: =K2*2250-IF(K2<$R$1,0,$R$2)+IF($P$1="是",IF(K2<$P$2,0,1000),0) -> 2250 | K2: 1 | L2: =K2*7+1 -> 8 | M2: 自选奇迹遗物·山 | N2: =IF($P$1="是",IF(K2<$P$2,M2,IF(K2=$P$2,M3,IF(K2=$P$2+1,M5,M2)))) -> 自选奇迹遗物·山 | O2: 跳期期数 | P2: =秘宝大作战!Q10 -> 16 | Q2: 漏获得能量 | R2: =秘宝大作战!R13 -> 150 | V2: 泽国数据 | AD2: 1 | AE2: 10 | AF2: 10 | AG2: 副本掉落装备升华率 | AH2: 0.03 | AI2: =COUNTIF(AG$1:AG2,AG2)*AH2 -> 0.03 | AK2: =泽国星象合约计算器!H2 -> 200 | AL2: =MATCH(AK2,$AF$2:$AF$65,1) -> 12 | AM2: =VLOOKUP(IF(MOD(AL2,4)<1,AL2-MOD(AL2,4)-3,AL2-MOD(AL2,4)+1),$AD$2:$AI$65,6,FALSE) -> 0.09 | AN2: =VLOOKUP(IF(MOD(AL2,4)<2,AL2-MOD(AL2,4)-2,AL2-MOD(AL2,4)+2),$AD$2:$AI$65,6,FALSE) -> 0.15 | AO2: =VLOOKUP(IF(MOD(AL2,4)<3,AL2-MOD(AL2,4)-1,AL2-MOD(AL2,4)+3),$AD$2:$AI$65,6,FALSE) -> 0.06 | AP2: =VLOOKUP(IF(MOD(AL2,4)<4,AL2-MOD(AL2,4),AL2-MOD(AL2,4)+4),$AD$2:$AI$65,6,FALSE) -> 0.06 | AU2: 等级 | AV2: 经验 | AW2: 等级 | AX2: 经验 | AY2: 等级 | AZ2: 经验 | BB2: 当前时间 | BC2: =NOW() -> 46180.438 | BE2: 等级列 | BF2: 当前等级行 | BG2: 当前目标行 | BI2: 森国 | BJ2: 3 | BK2: 5 | BL2: 3 | BM2: 0 | BN2: 0 | BO2: 0 | BR2: 金币价格 | BS2: =30/30000 -> 0.001 | BZ2: 161 | CA2: 26000 | CB2: =CA2*2 -> 52000 | CC2: =CA2*$BT$5+CB2*$BS$2 -> 312 | CD2: =CC2/14*13 -> 289.71429 | CE2: =(CA2/$BS$14*5+CB2/$BS$13*5)/14*13 -> 55.211437 | CG2: 161 | CH2: 19225 | CI2: 0 | CJ2: =CH2*$BT$6+CI2*$BS$2 -> 153.8 | CK2: =CJ2/5*13 -> 399.88 | CL2: =(CH2/$BS$15*5+CI2/$BS$13*5)/5*13 -> 83.308333 | CN2: 17 | CO2: 57500 | CP2: 103500 | CQ2: =CO2*$BT$7+CP2*$BS$2 -> 793.5 | CR2: =CQ2/26*13 -> 396.75 | CS2: =(CO2/$BS$16*5+CP2/$BS$13*5)/26*13 -> 75.609449 | CU2: 161 | CV2: 177350 | CW2: 0 | CX2: =CV2*$BT$8+CW2*$BS$2 -> 354.7 | CY2: =CX2/6*13 -> 768.51667 | DD2: 宝石等级 | DE2: 属性 | DF2: 升级成功率 | DG2: 蓄能值 | DH2: 必定成功次数 | DI2: 升级需要宝石数量 | DJ2: 每颗宝石获得属性 | DL2: 每10000战力所需晨星 | DN2: 幻兽材料价格 | DO2: =属性晨星性价比!B3 -> 80 | DQ2: 当前幻兽同调率 | DR2: =属性晨星性价比!C18 -> 1.24 | DT2: 实际面板 | EC2: 战力 | ED2: 2.5 | EE2: 2.5 | EF2: 0.5 | EG2: 3.125 | FB2: 等级 | FC2: 常规 | FD2: 朵菈 | FM2: 蓝色 | FN2: 0.7355 | FO2: 0.1246 | FQ2: 蓝色遗物当前星级 | FR2: =属性晨星性价比!R7 -> 0星 | FT2: 1星 | FU2: 1.2 | FW2: 防御 | FX2: 2.5
A3: 换一层 | B3: 换二层 | C3: 换三层 | D3: 换四层 | E3: 换五层 | F3: 不换 | G3: 换两个五层 | H3: 换三个五层 | J3: =K3*2250-IF(K3<$R$1,0,$R$2)+IF($P$1="是",IF(K3<$P$2,0,1000),0) -> 4500 | K3: 2 | L3: =K3*7+1 -> 15 | M3: 幸运神像 | N3: =IF($P$1="是",IF(K3<$P$2,M3,IF(K3=$P$2,M4,IF(K3=$P$2+1,M6,M3)))) -> 幸运神像 | O3: 跳期奖励 | P3: =IF(P1="是",VLOOKUP(P2,K:M,3,0),IF(P1="否","未跳期","错误")) -> 原初宝石 | V3: 角色等级 | W3: 装备强化等级 | X3: 技能强化等级 | Y3: 古遗物强化等级 | Z3: 幻兽等级 | AA3: 转化系数 | AB3: 固定原初 | AD3: 2 | AE3: 10 | AF3: =AF2+AE3 -> 20 | AG3: 宝石获取率 | AH3: 0.05 | AI3: =COUNTIF(AG$1:AG3,AG3)*AH3 -> 0.05 | AU3: 1 | AV3: 80 | AW3: 1 | AX3: 80 | AY3: 1 | AZ3: 80 | BB3: 当前赛季 | BC3: =#REF! -> #REF! | BD3: 龙国 | BE3: {=COLUMN(INDEX(1:1,MATCH(BD3,1:1,0)))-32} -> 17 | BF3: =BC4+2 -> #REF! | BG3: =BC5+2 -> #REF! | BI3: 山国 | BJ3: 4 | BK3: 3 | BL3: 5 | BM3: 3 | BN3: 0 | BO3: 0 | BZ3: 162 | CA3: =CA2+260 -> 26260 | CB3: =CA3*2 -> 52520 | CC3: =CA3*$BT$5+CB3*$BS$2 -> 315.12 | CD3: =CC3/14*13 -> 292.61143 | CE3: =(CA3/$BS$14*5+CB3/$BS$13*5)/14*13 -> 55.763551 | CG3: 162 | CH3: =CH2+190 -> 19415 | CI3: 0 | CJ3: =CH3*$BT$6+CI3*$BS$2 -> 155.32 | CK3: =CJ3/5*13 -> 403.832 | CL3: =(CH3/$BS$15*5+CI3/$BS$13*5)/5*13 -> 84.131667 | CN3: 18 | CO3: 63250 | CP3: =CP2+10350 -> 113850 | CQ3: =CO3*$BT$7+CP3*$BS$2 -> 872.85 | CR3: =CQ3/26*13 -> 436.425 | CS3: =(CO3/$BS$16*5+CP3/$BS$13*5)/26*13 -> 83.170394 | CU3: 162 | CV3: 180900 | CW3: 0 | CX3: =CV3*$BT$8+CW3*$BS$2 -> 361.8 | CY3: =CX3/6*13 -> 783.9 | DD3: 5 | DE3: 0.18 | DI3: 1 | DJ3: 0.18 | DK3: =FLOOR(10000*DJ3*MAX(DP$17*2.5,DP$18*2.5,DP$19*0.5,DP$20*3.125),1) -> 85428 | DL3: =DO$1/(DK3/10000) -> 84.2815 | DN3: 蓝食材价格 | DO3: =属性晨星性价比!B4 -> 15 | DQ3: 当前重置后幻兽面板 | DR3: 攻击力 | DS3: =属性晨星性价比!C19 -> 15 | DT3: =DS3/DR$2 -> 12.096774 | ED3: 攻击 | EE3: 攻击百分比 | EF3: 攻击节点 | EG3: 总攻击 | EH3: 总攻击百分比 | EI3: 防御 | EJ3: 防御百分比 | EK3: 防御节点 | EL3: 总防御 | EM3: 总防御百分比 | EN3: 生命 | EO3: 生命百分比 | EP3: 生命节点 | EQ3: 总生命 | ER3: 总生命百分比 | ES3: 速度 | ET3: 速度百分比 | EU3: 速度节点 | EV3: 总速度 | EW3: 总速度百分比 | EX3: 特殊节点 | EY3: 总节点数 | FB3: 1 | FC3: 900 | FD3: =SUM($FC$3:FC3) -> 900 | FM3: 紫色 | FN3: 0.1103 | FO3: 0.01 | FQ3: 蓝色遗物属性数值 | FR3: =属性晨星性价比!R8 -> 1.57 | FT3: 2星 | FU3: 1.4 | FW3: 生命 | FX3: 0.5
A4: =A2 -> 240 | B4: =A4+B2 -> 640 | C4: =B4+C2 -> 1240 | D4: =C4+D2 -> 2040 | E4: =D4+E2 -> 3240 | F4: 0 | G4: =E4+E2 -> 4440 | H4: =G4+E2 -> 5640 | J4: =K4*2250-IF(K4<$R$1,0,$R$2)+IF($P$1="是",IF(K4<$P$2,0,1000),0) -> 6750 | K4: 3 | L4: =K4*7+1 -> 22 | M4: 3阶技能碎片*180 | N4: =IF($P$1="是",IF(K4<$P$2,M4,IF(K4=$P$2,M5,IF(K4=$P$2+1,M7,M4)))) -> 3阶技能碎片*180 | O4: 补偿能量 | P4: =IF(P1="是",1000,IF(P1="否",0,"错误")) -> 1000 | V4: 100 | W4: 38 | X4: 13 | Y4: 57 | Z4: 14 | AA4: 100 | AB4: 10 | AD4: 3 | AE4: 10 | AF4: =AF3+AE4 -> 30 | AG4: 副本评价奖励翻倍概率 | AH4: 0.02 | AI4: =COUNTIF(AG$1:AG4,AG4)*AH4 -> 0.02 | AK4: 龙国选中原初之星数量 | AL4: 龙国原初档位 | AM4: 副本掉落装备升华率 | AN4: 宝石获取率 | AO4: 副本评价奖励翻倍概率 | AP4: 经验获取加成 | AU4: 2 | AV4: 90 | AW4: 2 | AX4: 90 | AY4: 2 | AZ4: 90 | BB4: 当前等级 | BC4: =#REF! -> #REF! | BD4: 经验值求和 | BE4: =SUM(INDEX(AU:AZ,BF3,BE3+1):INDEX(AU:AZ,BG3-1,BE3+1)) -> #REF! | BI4: 泽国 | BJ4: 5 | BK4: 2 | BL4: 3 | BM4: 6 | BN4: 0 | BO4: 0 | BR4: 材料名 | BS4: 金币价格 | BT4: 晨星价格 | BZ4: 163 | CA4: =CA3+260 -> 26520 | CB4: =CA4*2 -> 53040 | CC4: =CA4*$BT$5+CB4*$BS$2 -> 318.24 | CD4: =CC4/14*13 -> 295.50857 | CE4: =(CA4/$BS$14*5+CB4/$BS$13*5)/14*13 -> 56.315666 | CG4: 163 | CH4: =CH3+195 -> 19610 | CI4: 0 | CJ4: =CH4*$BT$6+CI4*$BS$2 -> 156.88 | CK4: =CJ4/5*13 -> 407.888 | CL4: =(CH4/$BS$15*5+CI4/$BS$13*5)/5*13 -> 84.976667 | CN4: 19 | CO4: 69000 | CP4: =CP3+10350 -> 124200 | CQ4: =CO4*$BT$7+CP4*$BS$2 -> 952.2 | CR4: =CQ4/26*13 -> 476.1 | CS4: =(CO4/$BS$16*5+CP4/$BS$13*5)/26*13 -> 90.731339 | CU4: 163 | CV4: 184450 | CW4: 0 | CX4: =CV4*$BT$8+CW4*$BS$2 -> 368.9 | CY4: =CX4/6*13 -> 799.28333 | DD4: 6 | DE4: =1.5*DE3 -> 0.27 | DF4: 1 | DG4: 1 | DH4: 1 | DI4: {=IF(DH4=1,1,SUM(_xlfn.SEQUENCE(DH4-1)*(1-DF4)^(_xlfn.SEQUENCE(DH4-1)-1)*DF4)+(1-DF4)^(DH4-1)*DH4)} -> 1 | DJ4: =DE3/2/DI4 -> 0.09 | DK4: =FLOOR(10000*DJ4*MAX(DP$17*2.5,DP$18*2.5,DP$19*0.5,DP$20*3.125),1) -> 42714 | DL4: =DO$1/(DK4/10000) -> 168.563 | DN4: 紫食材价格 | DO4: =属性晨星性价比!B5 -> 15 | DR4: 防御力 | DS4: =属性晨星性价比!C20 -> 15 | DT4: =DS4/DR$2 -> 12.096774 | EC4: 1 | ED4: 26 | EE4: 0.05 | EF4: 5 | EG4: =(4*EF4+2*($EY4-EF4))*ED4 -> 1248 | EH4: =EF4*EE4 -> 0.25 | EI4: 26 | EJ4: 0.05 | EK4: 5 | EL4: =(4*EK4+2*($EY4-EK4))*EI4 -> 1248 | EM4: =EK4*EJ4 -> 0.25 | EN4: 130 | EO4: 0.05 | EP4: 4 | EQ4: =(4*EP4+2*($EY4-EP4))*EN4 -> 5980 | ER4: =EP4*EO4 -> 0.2 | ES4: 20 | ET4: 0.05 | EU4: 4 | EV4: =(4*EU4+2*($EY4-EU4))*ES4 -> 920 | EW4: =EU4*ET4 -> 0.2 | EX4: 1 | EY4: =EF4+EK4+EP4+EU4+EX4 -> 19 | FB4: 2 | FC4: 1050 | FD4: =SUM($FC$3:FC4) -> 1950 | FL4: 蓝色 | FM4: 每抽碎片 | FN4: =FN2*3+FO2*20 -> 4.6985 | FO4: 每碎片价格 | FP4: =80/FN4 -> 17.026711 | FQ4: 星级倍率 | FR4: =VLOOKUP(FR2,FT1:FU7,2,0) -> 1 | FT4: 3星 | FU4: 1.6 | FW4: 速度 | FX4: 3.125
A5: 1 | B5: 2 | C5: 3 | D5: 4 | E5: 5 | F5: 0 | J5: =K5*2250-IF(K5<$R$1,0,$R$2)+IF($P$1="是",IF(K5<$P$2,0,1000),0) -> 9000 | K5: 4 | L5: =K5*7+1 -> 29 | M5: 原初宝石 | N5: =IF($P$1="是",IF(K5<$P$2,M5,IF(K5=$P$2,M6,IF(K5=$P$2+1,M8,M5)))) -> 原初宝石 | V5: 龙国数据 | AD5: 4 | AE5: 10 | AF5: =AF4+AE5 -> 40 | AG5: 经验获取加成 | AH5: 0.02 | AI5: =COUNTIF(AG$1:AG5,AG5)*AH5 -> 0.02 | AK5: =龙国星象合约计算器!H2 -> 1130 | AL5: =MATCH(AK5,$AF$2:$AF$65,1) -> 31 | AM5: =VLOOKUP(IF(MOD(AL5,4)<1,AL5-MOD(AL5,4)-3,AL5-MOD(AL5,4)+1),$AD$2:$AI$65,6,FALSE) -> 0.24 | AN5: =VLOOKUP(IF(MOD(AL5,4)<2,AL5-MOD(AL5,4)-2,AL5-MOD(AL5,4)+2),$AD$2:$AI$65,6,FALSE) -> 0.4 | AO5: =VLOOKUP(IF(MOD(AL5,4)<3,AL5-MOD(AL5,4)-1,AL5-MOD(AL5,4)+3),$AD$2:$AI$65,6,FALSE) -> 0.16 | AP5: =VLOOKUP(IF(MOD(AL5,4)<4,AL5-MOD(AL5,4),AL5-MOD(AL5,4)+4),$AD$2:$AI$65,6,FALSE) -> 0.14 | AU5: 3 | AV5: 90 | AW5: 3 | AX5: 90 | AY5: 3 | AZ5: 90 | BB5: 目标等级 | BC5: =#REF! -> #REF! | BI5: 龙国 | BJ5: 5 | BK5: 1 | BL5: 1 | BM5: 2 | BN5: 7 | BO5: 0 | BR5: 粗练石 | BS5: 10 | BT5: =$BS$2*BS5 -> 0.01 | BZ5: 164 | CA5: =CA4+260 -> 26780 | CB5: =CA5*2 -> 53560 | CC5: =CA5*$BT$5+CB5*$BS$2 -> 321.36 | CD5: =CC5/14*13 -> 298.40571 | CE5: =(CA5/$BS$14*5+CB5/$BS$13*5)/14*13 -> 56.86778 | CG5: 164 | CH5: =CH4+190 -> 19800 | CI5: 0 | CJ5: =CH5*$BT$6+CI5*$BS$2 -> 158.4 | CK5: =CJ5/5*13 -> 411.84 | CL5: =(CH5/$BS$15*5+CI5/$BS$13*5)/5*13 -> 85.8 | CN5: 20 | CO5: 74750 | CP5: =CP4+10350 -> 134550 | CQ5: =CO5*$BT$7+CP5*$BS$2 -> 1031.55 | CR5: =CQ5/26*13 -> 515.775 | CS5: =(CO5/$BS$16*5+CP5/$BS$13*5)/26*13 -> 98.292284 | CU5: 164 | CV5: 188000 | CW5: 0 | CX5: =CV5*$BT$8+CW5*$BS$2 -> 376 | CY5: =CX5/6*13 -> 814.66667 | DD5: 7 | DE5: =1.5*DE4 -> 0.405 | DF5: 0.36 | DG5: 0.5 | DH5: 3 | DI5: {=IF(DH5=1,1,SUM(_xlfn.SEQUENCE(DH5-1)*(1-DF5)^(_xlfn.SEQUENCE(DH5-1)-1)*DF5)+(1-DF5)^(DH5-1)*DH5)} -> 2.0496 | DJ5: =DE4/2/DI5 -> 0.065866511 | DK5: =FLOOR(10000*DJ5*MAX(DP$17*2.5,DP$18*2.5,DP$19*0.5,DP$20*3.125),1) -> 31260 | DL5: =DO$1/(DK5/10000) -> 230.3263 | DN5: 橙食材价格 | DO5: =属性晨星性价比!B6 -> 45 | DR5: 生命值 | DS5: =属性晨星性价比!C21 -> 75.3 | DT5: =DS5/DR$2 -> 60.725806 | EC5: 2 | ED5: 30 | EE5: 0.05 | EF5: 9 | EG5: =(4*EF5+2*($EY5-EF5))*ED5 -> 2580 | EH5: =EF5*EE5 -> 0.45 | EI5: 30 | EJ5: 0.05 | EK5: 8 | EL5: =(4*EK5+2*($EY5-EK5))*EI5 -> 2520 | EM5: =EK5*EJ5 -> 0.4 | EN5: 150 | EO5: 0.05 | EP5: 7 | EQ5: =(4*EP5+2*($EY5-EP5))*EN5 -> 12300 | ER5: =EP5*EO5 -> 0.35 | ES5: 24 | ET5: 0.05 | EU5: 8 | EV5: =(4*EU5+2*($EY5-EU5))*ES5 -> 2016 | EW5: =EU5*ET5 -> 0.4 | EX5: 2 | EY5: =EF5+EK5+EP5+EU5+EX5 -> 34 | FB5: 3 | FC5: 1200 | FD5: =SUM($FC$3:FC5) -> 3150 | FL5: 紫色 | FM5: 每抽碎片 | FN5: =FN3*3+FO3*30 -> 0.6309 | FO5: 每碎片价格 | FP5: =80/FN5 -> 126.80298 | FQ5: 战力倍率 | FR5: =VLOOKUP(FR1,FW1:FX4,2,0) -> 2.5 | FT5: 4星 | FU5: 1.8
J6: =K6*2250-IF(K6<$R$1,0,$R$2)+IF($P$1="是",IF(K6<$P$2,0,1000),0) -> 11250 | K6: 5 | L6: =K6*7+1 -> 36 | M6: 自选奇迹遗物·泽 | N6: =IF($P$1="是",IF(K6<$P$2,M6,IF(K6=$P$2,M7,IF(K6=$P$2+1,M9,M6)))) -> 自选奇迹遗物·泽 | V6: 角色等级 | W6: 装备强化等级 | X6: 技能强化等级 | Y6: 古遗物强化等级 | Z6: 幻兽等级 | AA6: 转化系数 | AB6: 固定原初 | AD6: 5 | AE6: 16 | AF6: =AF5+AE6 -> 56 | AG6: 副本掉落装备升华率 | AH6: 0.03 | AI6: =COUNTIF(AG$1:AG6,AG6)*AH6 -> 0.06 | AU6: 4 | AV6: 90 | AW6: 4 | AX6: 90 | AY6: 4 | AZ6: 90 | BB6: 当前经验 | BC6: =#REF! -> #REF! | BI6: 羽国 | BJ6: 5 | BK6: 0 | BL6: 2 | BM6: 2 | BN6: 2 | BO6: 5 | BR6: 历战精华 | BS6: 8 | BT6: =$BS$2*BS6 -> 0.008 | BZ6: 165 | CA6: =CA5+260 -> 27040 | CB6: =CA6*2 -> 54080 | CC6: =CA6*$BT$5+CB6*$BS$2 -> 324.48 | CD6: =CC6/14*13 -> 301.30286 | CE6: =(CA6/$BS$14*5+CB6/$BS$13*5)/14*13 -> 57.419894 | CG6: 165 | CH6: =CH5+195 -> 19995 | CI6: 0 | CJ6: =CH6*$BT$6+CI6*$BS$2 -> 159.96 | CK6: =CJ6/5*13 -> 415.896 | CL6: =(CH6/$BS$15*5+CI6/$BS$13*5)/5*13 -> 86.645 | CN6: 21 | CO6: 80500 | CP6: =CP5+10350 -> 144900 | CQ6: =CO6*$BT$7+CP6*$BS$2 -> 1110.9 | CR6: =CQ6/26*13 -> 555.45 | CS6: =(CO6/$BS$16*5+CP6/$BS$13*5)/26*13 -> 105.85323 | CU6: 165 | CV6: 191550 | CW6: 0 | CX6: =CV6*$BT$8+CW6*$BS$2 -> 383.1 | CY6: =CX6/6*13 -> 830.05 | DD6: 8 | DE6: =1.5*DE5 -> 0.6075 | DF6: 0.18 | DG6: 0.2 | DH6: 6 | DI6: {=IF(DH6=1,1,SUM(_xlfn.SEQUENCE(DH6-1)*(1-DF6)^(_xlfn.SEQUENCE(DH6-1)-1)*DF6)+(1-DF6)^(DH6-1)*DH6)} -> 3.8666296 | DJ6: =DE5/2/DI6 -> 0.052371192 | DK6: =FLOOR(10000*DJ6*MAX(DP$17*2.5,DP$18*2.5,DP$19*0.5,DP$20*3.125),1) -> 24855 | DL6: =DO$1/(DK6/10000) -> 289.68014 | DN6: 蓝肉价格 | DO6: =属性晨星性价比!B7 -> 40 | DR6: 速度 | DS6: =属性晨星性价比!C22 -> 12 | DT6: =DS6/DR$2 -> 9.6774194 | EC6: 3 | ED6: 36 | EE6: 0.05 | EF6: 6 | EG6: =(4*EF6+2*($EY6-EF6))*ED6 -> 2880 | EH6: =EF6*EE6 -> 0.3 | EI6: 36 | EJ6: 0.05 | EK6: 9 | EL6: =(4*EK6+2*($EY6-EK6))*EI6 -> 3096 | EM6: =EK6*EJ6 -> 0.45 | EN6: 180 | EO6: 0.05 | EP6: 9 | EQ6: =(4*EP6+2*($EY6-EP6))*EN6 -> 15480 | ER6: =EP6*EO6 -> 0.45 | ES6: 28 | ET6: 0.05 | EU6: 8 | EV6: =(4*EU6+2*($EY6-EU6))*ES6 -> 2352 | EW6: =EU6*ET6 -> 0.4 | EX6: 2 | EY6: =EF6+EK6+EP6+EU6+EX6 -> 34 | FB6: 4 | FC6: 1350 | FD6: =SUM($FC$3:FC6) -> 4500 | FQ6: 基准战力 | FR6: =FR3/FR4*FR5*10000 -> 39250 | FT6: 5星 | FU6: 2
J7: =K7*2250-IF(K7<$R$1,0,$R$2)+IF($P$1="是",IF(K7<$P$2,0,1000),0) -> 13500 | K7: 6 | L7: =K7*7+1 -> 43 | M7: 幸运神像 | N7: =IF($P$1="是",IF(K7<$P$2,M7,IF(K7=$P$2,M8,IF(K7=$P$2+1,M10,M7)))) -> 幸运神像 | O7: 合服调整 | P7: 损失天数 | Q7: 本应持续天数 | R7: 实际天数 | V7: 100 | W7: 18 | X7: 7 | Y7: 33 | Z7: 8 | AA7: 27 | AB7: 45 | AD7: 6 | AE7: 16 | AF7: =AF6+AE7 -> 72 | AG7: 宝石获取率 | AH7: 0.05 | AI7: =COUNTIF(AG$1:AG7,AG7)*AH7 -> 0.1 | AK7: 羽国选中原初之星数量 | AL7: 羽国原初档位 | AM7: 副本掉落装备升华率 | AN7: 宝石获取率 | AO7: 副本评价奖励翻倍概率 | AP7: 经验获取加成 | AU7: 5 | AV7: 90 | AW7: 5 | AX7: 90 | AY7: 5 | AZ7: 90 | BB7: 每小时经验 | BC7: =#REF! -> #REF! | BR7: 时之沙 | BS7: 12 | BT7: =$BS$2*BS7 -> 0.012 | BZ7: 166 | CA7: =CA6+260 -> 27300 | CB7: =CA7*2 -> 54600 | CC7: =CA7*$BT$5+CB7*$BS$2 -> 327.6 | CD7: =CC7/14*13 -> 304.2 | CE7: =(CA7/$BS$14*5+CB7/$BS$13*5)/14*13 -> 57.972009 | CG7: 166 | CH7: =CH6+190 -> 20185 | CI7: 0 | CJ7: =CH7*$BT$6+CI7*$BS$2 -> 161.48 | CK7: =CJ7/5*13 -> 419.848 | CL7: =(CH7/$BS$15*5+CI7/$BS$13*5)/5*13 -> 87.468333 | CN7: 22 | CO7: 86250 | CP7: =CP6+10350 -> 155250 | CQ7: =CO7*$BT$7+CP7*$BS$2 -> 1190.25 | CR7: =CQ7/26*13 -> 595.125 | CS7: =(CO7/$BS$16*5+CP7/$BS$13*5)/26*13 -> 113.41417 | CU7: 166 | CV7: 195100 | CW7: 0 | CX7: =CV7*$BT$8+CW7*$BS$2 -> 390.2 | CY7: =CX7/6*13 -> 845.43333 | DD7: 9 | DE7: =1.5*DE6 -> 0.91125 | DF7: 0.08 | DG7: 0.0909 | DH7: 12 | DI7: {=IF(DH7=1,1,SUM(_xlfn.SEQUENCE(DH7-1)*(1-DF7)^(_xlfn.SEQUENCE(DH7-1)-1)*DF7)+(1-DF7)^(DH7-1)*DH7)} -> 7.9041702 | DJ7: =DE6/2/DI7 -> 0.038429082 | DK7: =FLOOR(10000*DJ7*MAX(DP$17*2.5,DP$18*2.5,DP$19*0.5,DP$20*3.125),1) -> 18238 | DL7: =DO$1/(DK7/10000) -> 394.78013 | DN7: 紫肉价格 | DO7: =属性晨星性价比!B8 -> 40 | EC7: 4 | ED7: 42 | EE7: 0.05 | EF7: 9 | EG7: =(4*EF7+2*($EY7-EF7))*ED7 -> 3612 | EH7: =EF7*EE7 -> 0.45 | EI7: 42 | EJ7: 0.05 | EK7: 8 | EL7: =(4*EK7+2*($EY7-EK7))*EI7 -> 3528 | EM7: =EK7*EJ7 -> 0.4 | EN7: 210 | EO7: 0.05 | EP7: 8 | EQ7: =(4*EP7+2*($EY7-EP7))*EN7 -> 17640 | ER7: =EP7*EO7 -> 0.4 | ES7: 33 | ET7: 0.05 | EU7: 7 | EV7: =(4*EU7+2*($EY7-EU7))*ES7 -> 2706 | EW7: =EU7*ET7 -> 0.35 | EX7: 2 | EY7: =EF7+EK7+EP7+EU7+EX7 -> 34 | FB7: 5 | FC7: 1500 | FD7: =SUM($FC$3:FC7) -> 6000 | FT7: 觉醒 | FU7: 4
J8: =K8*2250-IF(K8<$R$1,0,$R$2)+IF($P$1="是",IF(K8<$P$2,0,1000),0) -> 15750 | K8: 7 | L8: =K8*7+1 -> 50 | M8: 4阶技能碎片*180 | N8: =IF($P$1="是",IF(K8<$P$2,M8,IF(K8=$P$2,M9,IF(K8=$P$2+1,M11,M8)))) -> 4阶技能碎片*180 | O8: 山国 | P8: =秘宝大作战!F1 -> 0 | Q8: 11 | V8: 羽国数据 | AD8: 7 | AE8: 16 | AF8: =AF7+AE8 -> 88 | AG8: 副本评价奖励翻倍概率 | AH8: 0.02 | AI8: =COUNTIF(AG$1:AG8,AG8)*AH8 -> 0.04 | AK8: =羽国星象合约计算器!H2 -> 3440 | AL8: =MATCH(AK8,$AF$2:$AF$65,1) -> 52 | AM8: =VLOOKUP(IF(MOD(AL8,4)<1,AL8-MOD(AL8,4)-3,AL8-MOD(AL8,4)+1),$AD$2:$AI$65,6,FALSE) -> 0.39 | AN8: =VLOOKUP(IF(MOD(AL8,4)<2,AL8-MOD(AL8,4)-2,AL8-MOD(AL8,4)+2),$AD$2:$AI$65,6,FALSE) -> 0.65 | AO8: =VLOOKUP(IF(MOD(AL8,4)<3,AL8-MOD(AL8,4)-1,AL8-MOD(AL8,4)+3),$AD$2:$AI$65,6,FALSE) -> 0.26 | AP8: =VLOOKUP(IF(MOD(AL8,4)<4,AL8-MOD(AL8,4),AL8-MOD(AL8,4)+4),$AD$2:$AI$65,6,FALSE) -> 0.26 | AU8: 6 | AV8: 90 | AW8: 6 | AX8: 90 | AY8: 6 | AZ8: 90 | BB8: 总经验缺口 | BC8: =BE4-BC6 -> #REF! | BR8: 幻兽经验 | BS8: 2 | BT8: =$BS$2*BS8 -> 0.002 | BZ8: 167 | CA8: =CA7+260 -> 27560 | CB8: =CA8*2 -> 55120 | CC8: =CA8*$BT$5+CB8*$BS$2 -> 330.72 | CD8: =CC8/14*13 -> 307.09714 | CE8: =(CA8/$BS$14*5+CB8/$BS$13*5)/14*13 -> 58.524123 | CG8: 167 | CH8: =CH7+195 -> 20380 | CI8: 0 | CJ8: =CH8*$BT$6+CI8*$BS$2 -> 163.04 | CK8: =CJ8/5*13 -> 423.904 | CL8: =(CH8/$BS$15*5+CI8/$BS$13*5)/5*13 -> 88.313333 | CN8: 23 | CO8: 92000 | CP8: =CP7+10350 -> 165600 | CQ8: =CO8*$BT$7+CP8*$BS$2 -> 1269.6 | CR8: =CQ8/26*13 -> 634.8 | CS8: =(CO8/$BS$16*5+CP8/$BS$13*5)/26*13 -> 120.97512 | CU8: 167 | CV8: 198650 | CW8: 0 | CX8: =CV8*$BT$8+CW8*$BS$2 -> 397.3 | CY8: =CX8/6*13 -> 860.81667 | DD8: 10 | DE8: =1.5*DE7 -> 1.366875 | DF8: 0.04 | DG8: 0.0435 | DH8: 24 | DI8: {=IF(DH8=1,1,SUM(_xlfn.SEQUENCE(DH8-1)*(1-DF8)^(_xlfn.SEQUENCE(DH8-1)-1)*DF8)+(1-DF8)^(DH8-1)*DH8)} -> 15.614669 | DJ8: =DE7/2/DI8 -> 0.029179293 | DK8: =FLOOR(10000*DJ8*MAX(DP$17*2.5,DP$18*2.5,DP$19*0.5,DP$20*3.125),1) -> 13848 | DL8: =DO$1/(DK8/10000) -> 519.93068 | DN8: 橙肉价格 | DO8: =属性晨星性价比!B9 -> 45 | EC8: 5 | ED8: 42 | EE8: 0.05 | EF8: 9 | EG8: =(4*EF8+2*($EY8-EF8))*ED8 -> 3612 | EH8: =EF8*EE8 -> 0.45 | EI8: 42 | EJ8: 0.05 | EK8: 8 | EL8: =(4*EK8+2*($EY8-EK8))*EI8 -> 3528 | EM8: =EK8*EJ8 -> 0.4 | EN8: 210 | EO8: 0.05 | EP8: 8 | EQ8: =(4*EP8+2*($EY8-EP8))*EN8 -> 17640 | ER8: =EP8*EO8 -> 0.4 | ES8: 33 | ET8: 0.05 | EU8: 7 | EV8: =(4*EU8+2*($EY8-EU8))*ES8 -> 2706 | EW8: =EU8*ET8 -> 0.35 | EX8: 2 | EY8: =EF8+EK8+EP8+EU8+EX8 -> 34 | FB8: 6 | FC8: 1530 | FD8: =SUM($FC$3:FC8) -> 7530
J9: =K9*2250-IF(K9<$R$1,0,$R$2)+IF($P$1="是",IF(K9<$P$2,0,1000),0) -> 18000 | K9: 8 | L9: =K9*7+1 -> 57 | M9: 原初宝石 | N9: =IF($P$1="是",IF(K9<$P$2,M9,IF(K9=$P$2,M10,IF(K9=$P$2+1,M12,M9)))) -> 原初宝石 | O9: 泽国 | P9: =秘宝大作战!H1 -> -1 | Q9: 35 | R9: =Q8+1+P8 -> 12 | V9: 角色等级 | W9: 装备强化等级 | X9: 技能强化等级 | Y9: 古遗物强化等级 | Z9: 幻兽等级 | AA9: 转化系数 | AB9: 固定原初 | AD9: 8 | AE9: 16 | AF9: =AF8+AE9 -> 104 | AG9: 经验获取加成 | AH9: 0.02 | AI9: =COUNTIF(AG$1:AG9,AG9)*AH9 -> 0.04 | AU9: 7 | AV9: 90 | AW9: 7 | AX9: 90 | AY9: 7 | AZ9: 90 | BB9: 加速次数 | BC9: =#REF! -> #REF! | BZ9: 168 | CA9: =CA8+260 -> 27820 | CB9: =CA9*2 -> 55640 | CC9: =CA9*$BT$5+CB9*$BS$2 -> 333.84 | CD9: =CC9/14*13 -> 309.99429 | CE9: =(CA9/$BS$14*5+CB9/$BS$13*5)/14*13 -> 59.076238 | CG9: 168 | CH9: =CH8+190 -> 20570 | CI9: 0 | CJ9: =CH9*$BT$6+CI9*$BS$2 -> 164.56 | CK9: =CJ9/5*13 -> 427.856 | CL9: =(CH9/$BS$15*5+CI9/$BS$13*5)/5*13 -> 89.136667 | CN9: 24 | CO9: 97750 | CP9: =CP8+10350 -> 175950 | CQ9: =CO9*$BT$7+CP9*$BS$2 -> 1348.95 | CR9: =CQ9/26*13 -> 674.475 | CS9: =(CO9/$BS$16*5+CP9/$BS$13*5)/26*13 -> 128.53606 | CU9: 168 | CV9: 202200 | CW9: 0 | CX9: =CV9*$BT$8+CW9*$BS$2 -> 404.4 | CY9: =CX9/6*13 -> 876.2 | DD9: 11 | DE9: =1.5*DE8 -> 2.0503125 | DF9: 1 | DG9: 1 | DH9: 1 | DI9: =SUM(DI3:DI8) -> 31.435069 | DJ9: =DE8/2/DI9 -> 0.021741244 | DK9: =FLOOR(10000*DJ9*MAX(DP$17*2.5,DP$18*2.5,DP$19*0.5,DP$20*3.125),1) -> 10318 | DL9: =DO$1/(DK9/10000) -> 697.80965 | EC9: 6 | ED9: 48 | EE9: 0.05 | EF9: 8 | EG9: =(4*EF9+2*($EY9-EF9))*ED9 -> 4032 | EH9: =EF9*EE9 -> 0.4 | EI9: 48 | EJ9: 0.05 | EK9: 8 | EL9: =(4*EK9+2*($EY9-EK9))*EI9 -> 4032 | EM9: =EK9*EJ9 -> 0.4 | EN9: 240 | EO9: 0.05 | EP9: 9 | EQ9: =(4*EP9+2*($EY9-EP9))*EN9 -> 20640 | ER9: =EP9*EO9 -> 0.45 | ES9: 38 | ET9: 0.05 | EU9: 7 | EV9: =(4*EU9+2*($EY9-EU9))*ES9 -> 3116 | EW9: =EU9*ET9 -> 0.35 | EX9: 2 | EY9: =EF9+EK9+EP9+EU9+EX9 -> 34 | FB9: 7 | FC9: 1560 | FD9: =SUM($FC$3:FC9) -> 9090
J10: =K10*2250-IF(K10<$R$1,0,$R$2)+IF($P$1="是",IF(K10<$P$2,0,1000),0) -> 20250 | K10: 9 | L10: =K10*7+1 -> 64 | M10: 自选奇迹遗物·龙I | N10: =IF($P$1="是",IF(K10<$P$2,M10,IF(K10=$P$2,M11,IF(K10=$P$2+1,M13,M10)))) -> 自选奇迹遗物·龙I | O10: 龙国 | P10: =秘宝大作战!J1 -> -1 | Q10: 67 | R10: =Q9+P9+R9 -> 46 | V10: 100 | W10: 14 | X10: 5 | Y10: 26 | Z10: 6 | AA10: 13 | AB10: 65 | AD10: 9 | AE10: 24 | AF10: =AF9+AE10 -> 128 | AG10: 副本掉落装备升华率 | AH10: 0.03 | AI10: =COUNTIF(AG$1:AG10,AG10)*AH10 -> 0.09 | AK10: 哈帕迪选中原初之星数量 | AL10: 羽国原初档位 | AM10: 副本掉落装备升华率 | AN10: 宝石获取率 | AO10: 副本评价奖励翻倍概率 | AP10: 经验获取加成 | AU10: 8 | AV10: 90 | AW10: 8 | AX10: 90 | AY10: 8 | AZ10: 90 | BB10: 加速石头次数 | BC10: =#REF! -> #REF! | BZ10: 169 | CA10: =CA9+260 -> 28080 | CB10: =CA10*2 -> 56160 | CC10: =CA10*$BT$5+CB10*$BS$2 -> 336.96 | CD10: =CC10/14*13 -> 312.89143 | CE10: =(CA10/$BS$14*5+CB10/$BS$13*5)/14*13 -> 59.628352 | CG10: 169 | CH10: =CH9+195 -> 20765 | CI10: 0 | CJ10: =CH10*$BT$6+CI10*$BS$2 -> 166.12 | CK10: =CJ10/5*13 -> 431.912 | CL10: =(CH10/$BS$15*5+CI10/$BS$13*5)/5*13 -> 89.981667 | CN10: 25 | CO10: 103500 | CP10: =CP9+10350 -> 186300 | CQ10: =CO10*$BT$7+CP10*$BS$2 -> 1428.3 | CR10: =CQ10/26*13 -> 714.15 | CS10: =(CO10/$BS$16*5+CP10/$BS$13*5)/26*13 -> 136.09701 | CU10: 169 | CV10: 205750 | CW10: 0 | CX10: =CV10*$BT$8+CW10*$BS$2 -> 411.5 | CY10: =CX10/6*13 -> 891.58333 | DD10: 12 | DE10: =1.5*DE9 -> 3.0754688 | DF10: 0.36 | DG10: 0.5 | DH10: 3 | DI10: {=IF(DH10=1,$DI$9,$DI$9*(SUM(_xlfn.SEQUENCE(DH10-1)*(1-DF10)^(_xlfn.SEQUENCE(DH10-1)-1)*DF10)+(1-DF10)^(DH10-1)*DH10))} -> 64.429317 | DJ10: =DE9/2/DI10 -> 0.015911332 | DK10: =FLOOR(10000*DJ10*MAX(DP$17*2.5,DP$18*2.5,DP$19*0.5,DP$20*3.125),1) -> 7551 | DL10: =DO$1/(DK10/10000) -> 953.51609 | EC10: 7 | ED10: 48 | EE10: 0.05 | EF10: 9 | EG10: =(4*EF10+2*($EY10-EF10))*ED10 -> 4128 | EH10: =EF10*EE10 -> 0.45 | EI10: 48 | EJ10: 0.05 | EK10: 6 | EL10: =(4*EK10+2*($EY10-EK10))*EI10 -> 3840 | EM10: =EK10*EJ10 -> 0.3 | EN10: 240 | EO10: 0.05 | EP10: 9 | EQ10: =(4*EP10+2*($EY10-EP10))*EN10 -> 20640 | ER10: =EP10*EO10 -> 0.45 | ES10: 38 | ET10: 0.05 | EU10: 8 | EV10: =(4*EU10+2*($EY10-EU10))*ES10 -> 3192 | EW10: =EU10*ET10 -> 0.4 | EX10: 2 | EY10: =EF10+EK10+EP10+EU10+EX10 -> 34 | FB10: 8 | FC10: 1590 | FD10: =SUM($FC$3:FC10) -> 10680 | FM10: 蓝色 | FO10: 20 | FP10: 20 | FQ10: 40 | FR10: 60 | FS10: 80 | FT10: 100 | FU10: 120
A11: 期数 | B11: 能量盈亏 | C11: 能量缺口 | D11: 6元 | E11: 30元 | F11: 额外缺口 | J11: =K11*2250-IF(K11<$R$1,0,$R$2)+IF($P$1="是",IF(K11<$P$2,0,1000),0) -> 22350 | K11: 10 | L11: =K11*7+1 -> 71 | M11: 幸运神像 | N11: =IF($P$1="是",IF(K11<$P$2,M11,IF(K11=$P$2,M12,IF(K11=$P$2+1,M14,M11)))) -> 幸运神像 | O11: 羽国 | P11: =秘宝大作战!L1 -> -1 | Q11: 101 | R11: =Q10+P10+R10 -> 112 | V11: 哈帕迪数据 | AD11: 10 | AE11: 24 | AF11: =AF10+AE11 -> 152 | AG11: 宝石获取率 | AH11: 0.05 | AI11: =COUNTIF(AG$1:AG11,AG11)*AH11 -> 0.15 | AK11: =哈帕迪星象合约计算器!H2 -> 9080 | AL11: =MATCH(AK11,$AF$2:$AF$89,1) -> 80 | AM11: =VLOOKUP(IF(MOD(AL11,4)<1,AL11-MOD(AL11,4)-3,AL11-MOD(AL11,4)+1),$AD$2:$AI$89,6,FALSE) -> 0.6 | AN11: =VLOOKUP(IF(MOD(AL11,4)<2,AL11-MOD(AL11,4)-2,AL11-MOD(AL11,4)+2),$AD$2:$AI$89,6,FALSE) -> 1 | AO11: =VLOOKUP(IF(MOD(AL11,4)<3,AL11-MOD(AL11,4)-1,AL11-MOD(AL11,4)+3),$AD$2:$AI$89,6,FALSE) -> 0.4 | AP11: =VLOOKUP(IF(MOD(AL11,4)<4,AL11-MOD(AL11,4),AL11-MOD(AL11,4)+4),$AD$2:$AI$89,6,FALSE) -> 0.4 | AU11: 9 | AV11: 100 | AW11: 9 | AX11: 100 | AY11: 9 | AZ11: 100 | BB11: 剩余升级时间 | BC11: =BC8/BC7/24+BC2 -> #REF! | BZ11: 170 | CA11: =CA10+260 -> 28340 | CB11: =CA11*2 -> 56680 | CC11: =CA11*$BT$5+CB11*$BS$2 -> 340.08 | CD11: =CC11/14*13 -> 315.78857 | CE11: =(CA11/$BS$14*5+CB11/$BS$13*5)/14*13 -> 60.180466 | CG11: 170 | CH11: =CH10+190 -> 20955 | CI11: 0 | CJ11: =CH11*$BT$6+CI11*$BS$2 -> 167.64 | CK11: =CJ11/5*13 -> 435.864 | CL11: =(CH11/$BS$15*5+CI11/$BS$13*5)/5*13 -> 90.805 | CN11: 26 | CO11: 109250 | CP11: =CP10+10350 -> 196650 | CQ11: =CO11*$BT$7+CP11*$BS$2 -> 1507.65 | CR11: =CQ11/26*13 -> 753.825 | CS11: =(CO11/$BS$16*5+CP11/$BS$13*5)/26*13 -> 143.65795 | CU11: 170 | CV11: 209300 | CW11: 0 | CX11: =CV11*$BT$8+CW11*$BS$2 -> 418.6 | CY11: =CX11/6*13 -> 906.96667 | DD11: 13 | DE11: =1.5*DE10 -> 4.6132031 | DF11: 0.18 | DG11: 0.2 | DH11: 6 | DI11: {=IF(DH11=1,$DI$9,$DI$9*(SUM(_xlfn.SEQUENCE(DH11-1)*(1-DF11)^(_xlfn.SEQUENCE(DH11-1)-1)*DF11)+(1-DF11)^(DH11-1)*DH11))} -> 121.54777 | DJ11: =DE10/2/DI11 -> 0.012651276 | DK11: =FLOOR(10000*DJ11*MAX(DP$17*2.5,DP$18*2.5,DP$19*0.5,DP$20*3.125),1) -> 6004 | DL11: =DO$1/(DK11/10000) -> 1199.2005 | EC11: 8 | ED11: 48 | EE11: 0.05 | EF11: 8 | EG11: =(4*EF11+2*($EY11-EF11))*ED11 -> 4032 | EH11: =EF11*EE11 -> 0.4 | EI11: 48 | EJ11: 0.05 | EK11: 9 | EL11: =(4*EK11+2*($EY11-EK11))*EI11 -> 4128 | EM11: =EK11*EJ11 -> 0.45 | EN11: 240 | EO11: 0.05 | EP11: 7 | EQ11: =(4*EP11+2*($EY11-EP11))*EN11 -> 19680 | ER11: =EP11*EO11 -> 0.35 | ES11: 38 | ET11: 0.05 | EU11: 8 | EV11: =(4*EU11+2*($EY11-EU11))*ES11 -> 3192 | EW11: =EU11*ET11 -> 0.4 | EX11: 2 | EY11: =EF11+EK11+EP11+EU11+EX11 -> 34 | FB11: 9 | FC11: 1620 | FD11: =SUM($FC$3:FC11) -> 12300 | FG11: 橙首饰 | FH11: 紫首饰 | FI11: 蓝首饰 | FN11: 战力差 | FO11: =$FR$6 -> 39250 | FP11: =0.2*$FR$6 -> 7850 | FQ11: =0.2*$FR$6 -> 7850 | FR11: =0.2*$FR$6 -> 7850 | FS11: =0.2*$FR$6 -> 7850 | FT11: =0.2*$FR$6 -> 7850 | FU11: =2*$FR$6 -> 78500
A12: 1 | B12: =秘宝大作战!D3-秘宝大作战!H3 -> -990 | C12: =IF(B12<0,-B12,0) -> 990 | D12: =IF(C12>0,A12*2*60,0) -> 120 | E12: =IF(C12>0,A12*2*300,0) -> 600 | F12: =IF(C12-D12-E12>0,C12-D12-E12,0) -> 270 | J12: =K12*2250-IF(K12<$R$1,0,$R$2)+IF($P$1="是",IF(K12<$P$2,0,1000),0) -> 24600 | K12: 11 | L12: =K12*7+1 -> 78 | M12: 4阶技能碎片*180 | N12: =IF($P$1="是",IF(K12<$P$2,M12,IF(K12=$P$2,M13,IF(K12=$P$2+1,M15,M12)))) -> 4阶技能碎片*180 | O12: 哈帕迪 | P12: =秘宝大作战!N1 -> -4 | R12: =Q11+P11+R11 -> 212 | V12: 角色等级 | W12: 装备强化等级 | X12: 技能强化等级 | Y12: 古遗物强化等级 | Z12: 幻兽等级 | AA12: 转化系数 | AB12: 固定原初 | AD12: 11 | AE12: 24 | AF12: =AF11+AE12 -> 176 | AG12: 副本评价奖励翻倍概率 | AH12: 0.02 | AI12: =COUNTIF(AG$1:AG12,AG12)*AH12 -> 0.06 | AU12: 10 | AV12: 350 | AW12: 10 | AX12: 350 | AY12: 10 | AZ12: 350 | BB12: 加速后升级时间 | BC12: =(BC8/BC7-(BC9+BC10)*2)/24+BC2 -> #REF! | BS12: 5体力产出 | BZ12: 171 | CA12: =CA11+260 -> 28600 | CB12: =CA12*2 -> 57200 | CC12: =CA12*$BT$5+CB12*$BS$2 -> 343.2 | CD12: =CC12/14*13 -> 318.68571 | CE12: =(CA12/$BS$14*5+CB12/$BS$13*5)/14*13 -> 60.732581 | CG12: 171 | CH12: =CH11+195 -> 21150 | CI12: 0 | CJ12: =CH12*$BT$6+CI12*$BS$2 -> 169.2 | CK12: =CJ12/5*13 -> 439.92 | CL12: =(CH12/$BS$15*5+CI12/$BS$13*5)/5*13 -> 91.65 | CN12: 27 | CO12: 115000 | CP12: =CP11+10350 -> 207000 | CQ12: =CO12*$BT$7+CP12*$BS$2 -> 1587 | CR12: =CQ12/26*13 -> 793.5 | CS12: =(CO12/$BS$16*5+CP12/$BS$13*5)/26*13 -> 151.2189 | CU12: 171 | CV12: 212850 | CW12: 0 | CX12: =CV12*$BT$8+CW12*$BS$2 -> 425.7 | CY12: =CX12/6*13 -> 922.35 | DD12: 14 | DE12: =1.5*DE11 -> 6.9198047 | DF12: 0.08 | DG12: 0.0909 | DH12: 12 | DI12: {=IF(DH12=1,$DI$9,$DI$9*(SUM(_xlfn.SEQUENCE(DH12-1)*(1-DF12)^(_xlfn.SEQUENCE(DH12-1)-1)*DF12)+(1-DF12)^(DH12-1)*DH12))} -> 248.46813 | DJ12: =DE11/2/DI12 -> 0.0092832894 | DK12: =FLOOR(10000*DJ12*MAX(DP$17*2.5,DP$18*2.5,DP$19*0.5,DP$20*3.125),1) -> 4405 | DL12: =DO$1/(DK12/10000) -> 1634.5062 | FB12: 10 | FC12: 1680 | FD12: =SUM($FC$3:FC12) -> 13980 | FF12: 已囤礼物 | FG12: 0 | FH12: 0 | FI12: 0 | FN12: 每碎片战力 | FO12: =FO11/FO10 -> 1962.5 | FP12: =FP11/FP10 -> 392.5 | FQ12: =FQ11/FQ10 -> 196.25 | FR12: =FR11/FR10 -> 130.83333 | FS12: =FS11/FS10 -> 98.125 | FT12: =FT11/FT10 -> 78.5 | FU12: =FU11/FU10 -> 654.16667
A13: 2 | B13: =秘宝大作战!D4-秘宝大作战!H4 -> -1980 | C13: =IF(B13<0,-B13,0) -> 1980 | D13: =IF(C13>0,A13*2*60,0) -> 240 | E13: =IF(C13>0,A13*2*300,0) -> 1200 | F13: =IF(C13-D13-E13>0,C13-D13-E13,0) -> 540 | J13: =K13*2250-IF(K13<$R$1,0,$R$2)+IF($P$1="是",IF(K13<$P$2,0,1000),0) -> 26850 | K13: 12 | L13: =K13*7+1 -> 85 | M13: 原初宝石 | N13: =IF($P$1="是",IF(K13<$P$2,M13,IF(K13=$P$2,M14,IF(K13=$P$2+1,M16,M13)))) -> 原初宝石 | V13: 100 | W13: 17 | X13: 5 | Y13: 28 | Z13: 11 | AA13: 7 | AB13: 120 | AD13: 12 | AE13: 24 | AF13: =AF12+AE13 -> 200 | AG13: 经验获取加成 | AH13: 0.02 | AI13: =COUNTIF(AG$1:AG13,AG13)*AH13 -> 0.06 | AU13: 11 | AV13: 355 | AW13: 11 | AX13: 355 | AY13: 11 | AZ13: 355 | BR13: 金币 | BS13: =24000*(1+0.0932) -> 26236.8 | BZ13: 172 | CA13: =CA12+260 -> 28860 | CB13: =CA13*2 -> 57720 | CC13: =CA13*$BT$5+CB13*$BS$2 -> 346.32 | CD13: =CC13/14*13 -> 321.58286 | CE13: =(CA13/$BS$14*5+CB13/$BS$13*5)/14*13 -> 61.284695 | CG13: 172 | CH13: =CH12+190 -> 21340 | CI13: 0 | CJ13: =CH13*$BT$6+CI13*$BS$2 -> 170.72 | CK13: =CJ13/5*13 -> 443.872 | CL13: =(CH13/$BS$15*5+CI13/$BS$13*5)/5*13 -> 92.473333 | CN13: 28 | CO13: 120750 | CP13: =CP12+10350 -> 217350 | CQ13: =CO13*$BT$7+CP13*$BS$2 -> 1666.35 | CR13: =CQ13/26*13 -> 833.175 | CS13: =(CO13/$BS$16*5+CP13/$BS$13*5)/26*13 -> 158.77984 | CU13: 172 | CV13: 216400 | CW13: 0 | CX13: =CV13*$BT$8+CW13*$BS$2 -> 432.8 | CY13: =CX13/6*13 -> 937.73333 | FB13: 11 | FC13: 1740 | FD13: =SUM($FC$3:FC13) -> 15720 | FF13: 已囤首饰类经验 | FI13: =FG12*3000+FH12*1000+FI12*200 -> 0 | FN13: 1w战力价格 | FO13: =10000/FO12*$FP$4 -> 86.760309 | FP13: =10000/FP12*$FP$4 -> 433.80155 | FQ13: =10000/FQ12*$FP$4 -> 867.60309 | FR13: =10000/FR12*$FP$4 -> 1301.4046 | FS13: =10000/FS12*$FP$4 -> 1735.2062 | FT13: =10000/FT12*$FP$4 -> 2169.0077 | FU13: =10000/FU12*$FP$4 -> 260.28093
A14: 3 | B14: =秘宝大作战!D5-秘宝大作战!H5 -> -2970 | C14: =IF(B14<0,-B14,0) -> 2970 | D14: =IF(C14>0,A14*2*60,0) -> 360 | E14: =IF(C14>0,A14*2*300,0) -> 1800 | F14: =IF(C14-D14-E14>0,C14-D14-E14,0) -> 810 | J14: =K14*2250-IF(K14<$R$1,0,$R$2)+IF($P$1="是",IF(K14<$P$2,0,1000),0) -> 29100 | K14: 13 | L14: =K14*7+1 -> 92 | M14: 自选奇迹遗物·龙II | N14: =IF($P$1="是",IF(K14<$P$2,M14,IF(K14=$P$2,M15,IF(K14=$P$2+1,M17,M14)))) -> 自选奇迹遗物·龙II | AD14: 13 | AE14: 30 | AF14: =AF13+AE14 -> 230 | AG14: 副本掉落装备升华率 | AH14: 0.03 | AI14: =COUNTIF(AG$1:AG14,AG14)*AH14 -> 0.12 | AU14: 12 | AV14: 360 | AW14: 12 | AX14: 360 | AY14: 12 | AZ14: 360 | BR14: 粗练石 | BS14: =2400*(1+0.0932) -> 2623.68 | BZ14: 173 | CA14: =CA13+260 -> 29120 | CB14: =CA14*2 -> 58240 | CC14: =CA14*$BT$5+CB14*$BS$2 -> 349.44 | CD14: =CC14/14*13 -> 324.48 | CE14: =(CA14/$BS$14*5+CB14/$BS$13*5)/14*13 -> 61.836809 | CG14: 173 | CH14: =CH13+195 -> 21535 | CI14: 0 | CJ14: =CH14*$BT$6+CI14*$BS$2 -> 172.28 | CK14: =CJ14/5*13 -> 447.928 | CL14: =(CH14/$BS$15*5+CI14/$BS$13*5)/5*13 -> 93.318333 | CN14: 29 | CO14: 126500 | CP14: =CP13+10350 -> 227700 | CQ14: =CO14*$BT$7+CP14*$BS$2 -> 1745.7 | CR14: =CQ14/26*13 -> 872.85 | CS14: =(CO14/$BS$16*5+CP14/$BS$13*5)/26*13 -> 166.34079 | CU14: 173 | CV14: 219950 | CW14: 0 | CX14: =CV14*$BT$8+CW14*$BS$2 -> 439.9 | CY14: =CX14/6*13 -> 953.11667 | DD14: 幻兽 | FB14: 12 | FC14: 1800 | FD14: =SUM($FC$3:FC14) -> 17520 | FF14: 朵菈当前等级 | FG14: 81 | FH14: 好感度 | FI14: 3980 | FN14: 综合每碎片战力 | FO14: =(SUM(FO11:FU11)/SUM(FO10:FU10)) -> 356.81818
A15: 4 | B15: =秘宝大作战!D6-秘宝大作战!H6 -> -3960 | C15: =IF(B15<0,-B15,0) -> 3960 | D15: =IF(C15>0,A15*2*60,0) -> 480 | E15: =IF(C15>0,A15*2*300,0) -> 2400 | F15: =IF(C15-D15-E15>0,C15-D15-E15,0) -> 1080 | J15: =K15*2250-IF(K15<$R$1,0,$R$2)+IF($P$1="是",IF(K15<$P$2,0,1000),0) -> 31350 | K15: 14 | L15: =K15*7+1 -> 99 | M15: 幸运神像 | N15: =IF($P$1="是",IF(K15<$P$2,M15,IF(K15=$P$2,M16,IF(K15=$P$2+1,M18,M15)))) -> 幸运神像 | V15: 泽国计算 | AD15: 14 | AE15: 30 | AF15: =AF14+AE15 -> 260 | AG15: 宝石获取率 | AH15: 0.05 | AI15: =COUNTIF(AG$1:AG15,AG15)*AH15 -> 0.2 | AU15: 13 | AV15: 370 | AW15: 13 | AX15: 370 | AY15: 13 | AZ15: 370 | BR15: 历战精华 | BS15: 3000 | BZ15: 174 | CA15: =CA14+260 -> 29380 | CB15: =CA15*2 -> 58760 | CC15: =CA15*$BT$5+CB15*$BS$2 -> 352.56 | CD15: =CC15/14*13 -> 327.37714 | CE15: =(CA15/$BS$14*5+CB15/$BS$13*5)/14*13 -> 62.388924 | CG15: 174 | CH15: =CH14+190 -> 21725 | CI15: 0 | CJ15: =CH15*$BT$6+CI15*$BS$2 -> 173.8 | CK15: =CJ15/5*13 -> 451.88 | CL15: =(CH15/$BS$15*5+CI15/$BS$13*5)/5*13 -> 94.141667 | CN15: 30 | CO15: 132250 | CP15: =CP14+10350 -> 238050 | CQ15: =CO15*$BT$7+CP15*$BS$2 -> 1825.05 | CR15: =CQ15/26*13 -> 912.525 | CS15: =(CO15/$BS$16*5+CP15/$BS$13*5)/26*13 -> 173.90173 | CU15: 174 | CV15: 223500 | CW15: 0 | CX15: =CV15*$BT$8+CW15*$BS$2 -> 447 | CY15: =CX15/6*13 -> 968.5 | DD15: 蓝色 | FB15: 13 | FC15: 1860 | FD15: =SUM($FC$3:FC15) -> 19380 | FF15: 朵菈当前累计经验 | FI15: =VLOOKUP(FG14-1,FB3:FD101,3,0)+FI14 -> 398480 | FM15: 紫色 | FO15: 30 | FP15: 30 | FQ15: 60 | FR15: 90 | FS15: 120 | FT15: 150 | FU15: 180
A16: 5 | B16: =秘宝大作战!D7-秘宝大作战!H7 -> -6150 | C16: =IF(B16<0,-B16,0) -> 6150 | D16: =IF(C16>0,A16*2*60,0) -> 600 | E16: =IF(C16>0,A16*2*300,0) -> 3000 | F16: =IF(C16-D16-E16>0,C16-D16-E16,0) -> 2550 | J16: =K16*2250-IF(K16<$R$1,0,$R$2)+IF($P$1="是",IF(K16<$P$2,0,1000),0) -> 33600 | K16: 15 | L16: =K16*7+1 -> 106 | M16: 4阶技能碎片*180 | N16: =IF($P$1="是",IF(K16<$P$2,M16,IF(K16=$P$2,M17,IF(K16=$P$2+1,M19,M16)))) -> 4阶技能碎片*180 | V16: 角色等级 | W16: 装备强化等级 | X16: 技能强化等级 | Y16: 古遗物强化等级 | Z16: 幻兽等级 | AA16: 总分 | AD16: 15 | AE16: 30 | AF16: =AF15+AE16 -> 290 | AG16: 副本评价奖励翻倍概率 | AH16: 0.02 | AI16: =COUNTIF(AG$1:AG16,AG16)*AH16 -> 0.08 | AU16: 14 | AV16: 375 | AW16: 14 | AX16: 375 | AY16: 14 | AZ16: 375 | BR16: 时之沙 | BS16: =2000*(1+0.0932) -> 2186.4 | BZ16: 175 | CA16: =CA15+260 -> 29640 | CB16: =CA16*2 -> 59280 | CC16: =CA16*$BT$5+CB16*$BS$2 -> 355.68 | CD16: =CC16/14*13 -> 330.27429 | CE16: =(CA16/$BS$14*5+CB16/$BS$13*5)/14*13 -> 62.941038 | CG16: 175 | CH16: =CH15+195 -> 21920 | CI16: 0 | CJ16: =CH16*$BT$6+CI16*$BS$2 -> 175.36 | CK16: =CJ16/5*13 -> 455.936 | CL16: =(CH16/$BS$15*5+CI16/$BS$13*5)/5*13 -> 94.986667 | CN16: 31 | CO16: 138000 | CP16: =CP15+10350 -> 248400 | CQ16: =CO16*$BT$7+CP16*$BS$2 -> 1904.4 | CR16: =CQ16/26*13 -> 952.2 | CS16: =(CO16/$BS$16*5+CP16/$BS$13*5)/26*13 -> 181.46268 | CU16: 175 | CV16: 227050 | CW16: 0 | CX16: =CV16*$BT$8+CW16*$BS$2 -> 454.1 | CY16: =CX16/6*13 -> 983.88333 | DE16: 总固定属性战力 | DF16: 总常规属性战力 | DG16: 所需蓝材料 | DK16: 每1万战力所需晨星 | DN16: 职业属性 | DO16: 职业加成 | DP16: 实际属性 | EC16: 选择幻兽品质 | ED16: =幻兽同调计算器!C1 -> 奇迹 | EE16: =IF(ED16="奇迹",4/3,1) -> 1.3333333 | EF16: =IF(ED16="奇迹",1.2,1.1) -> 1.2 | EH16: 对比幻兽品质 | EI16: =幻兽同调计算器!H1 -> 传说 | EJ16: =IF(EI16="奇迹",4/3,1) -> 1 | EK16: =IF(EI16="奇迹",1.2,1.1) -> 1.1 | FB16: 14 | FC16: 1920 | FD16: =SUM($FC$3:FC16) -> 21300 | FF16: 朵菈100级已囤积进度 | FN16: 战力差 | FO16: =2*$FR$6 -> 78500 | FP16: =2*0.2*$FR$6 -> 15700 | FQ16: =2*0.2*$FR$6 -> 15700 | FR16: =2*0.2*$FR$6 -> 15700 | FS16: =2*0.2*$FR$6 -> 15700 | FT16: =2*0.2*$FR$6 -> 15700 | FU16: =2*2*$FR$6 -> 157000
A17: 6 | B17: =秘宝大作战!D8-秘宝大作战!H8 -> -7140 | C17: =IF(B17<0,-B17,0) -> 7140 | D17: =IF(C17>0,A17*2*60,0) -> 720 | E17: =IF(C17>0,A17*2*300,0) -> 3600 | F17: =IF(C17-D17-E17>0,C17-D17-E17,0) -> 2820 | J17: =K17*2250-IF(K17<$R$1,0,$R$2)+IF($P$1="是",IF(K17<$P$2,0,1000),0) -> 36850 | K17: 16 | L17: =K17*7+1 -> 113 | M17: 原初宝石 | N17: =IF($P$1="是",IF(K17<$P$2,M17,IF(K17=$P$2,M18,IF(K17=$P$2+1,M20,M17)))) -> 自选奇迹遗物·羽I | V17: =(泽国星象合约计算器!B2-100)*V4 -> 2304 | W17: =(SUM(泽国星象合约计算器!B4:C6)-5*100)*W4 -> 4560 | X17: =(SUM(泽国星象合约计算器!B8:C11)-8*100)*X4 -> 1872 | Y17: =(SUM(泽国星象合约计算器!B13:E17)-20*10)*Y4 -> 2451 | Z17: =(SUM(泽国星象合约计算器!B19:E19)-4*100)*Z4 -> 616 | AA17: =SUM(V17:Z17) -> 11803 | AD17: 16 | AE17: 30 | AF17: =AF16+AE17 -> 320 | AG17: 经验获取加成 | AH17: 0.02 | AI17: =COUNTIF(AG$1:AG17,AG17)*AH17 -> 0.08 | AU17: 15 | AV17: 390 | AW17: 15 | AX17: 390 | AY17: 15 | AZ17: 390 | BZ17: 176 | CA17: =CA16+260 -> 29900 | CB17: =CA17*2 -> 59800 | CC17: =CA17*$BT$5+CB17*$BS$2 -> 358.8 | CD17: =CC17/14*13 -> 333.17143 | CE17: =(CA17/$BS$14*5+CB17/$BS$13*5)/14*13 -> 63.493152 | CG17: 176 | CH17: =CH16+190 -> 22110 | CI17: 0 | CJ17: =CH17*$BT$6+CI17*$BS$2 -> 176.88 | CK17: =CJ17/5*13 -> 459.888 | CL17: =(CH17/$BS$15*5+CI17/$BS$13*5)/5*13 -> 95.81 | CN17: 32 | CO17: 143750 | CP17: =CP16+10350 -> 258750 | CQ17: =CO17*$BT$7+CP17*$BS$2 -> 1983.75 | CR17: =CQ17/26*13 -> 991.875 | CS17: =(CO17/$BS$16*5+CP17/$BS$13*5)/26*13 -> 189.02362 | CU17: 176 | CV17: 230600 | CW17: 0 | CX17: =CV17*$BT$8+CW17*$BS$2 -> 461.2 | CY17: =CX17/6*13 -> 999.26667 | DD17: 第1页 | DE17: =SUM($DH$29*2.5,$DM$29*2.5,$DR$29*0.5,$DW$29*3.125) -> 5155 | DF17: =10000*($DI$29*DT$3*2.5+$DN$29*DT$4*2.5+$DS$29*DT$5*0.5+$DX$29*DT$6*3.125) -> 272419.35 | DG17: 570 | DJ17: 第1页 | DK17: =DG17/16*DO$2/((DE17*DT$1+DF17*DT$1)*DR$2/10000) -> 69.002145 | DM17: 攻击 | DN17: =属性晨星性价比!I2 -> 11.3 | DO17: =属性晨星性价比!I7 -> 0.68 | DP17: =DN17*(1+DO17) -> 18.984 | EC17: 当前幻兽同调率 | ED17: =幻兽同调计算器!C2 -> 1.36 | EF17: 战力 | EH17: 对比幻兽同调 | EI17: =幻兽同调计算器!H2 -> 1.49 | EK17: 战力 | FB17: 15 | FC17: 1980 | FD17: =SUM($FC$3:FC17) -> 23280 | FF17: ="已囤总经验需求的"&TEXT(ROUND((FI13+FI15)/FC102,4),"0.00%") -> 已囤总经验需求的60.91% | FN17: 每碎片战力 | FO17: =FO16/FO15 -> 2616.6667 | FP17: =FP16/FP15 -> 523.33333 | FQ17: =FQ16/FQ15 -> 261.66667 | FR17: =FR16/FR15 -> 174.44444 | FS17: =FS16/FS15 -> 130.83333 | FT17: =FT16/FT15 -> 104.66667 | FU17: =FU16/FU15 -> 872.22222
A18: 7 | B18: =秘宝大作战!D9-秘宝大作战!H9 -> -8130 | C18: =IF(B18<0,-B18,0) -> 8130 | D18: =IF(C18>0,A18*2*60,0) -> 840 | E18: =IF(C18>0,A18*2*300,0) -> 4200 | F18: =IF(C18-D18-E18>0,C18-D18-E18,0) -> 3090 | J18: =K18*2250-IF(K18<$R$1,0,$R$2)+IF($P$1="是",IF(K18<$P$2,0,1000),0) -> 39100 | K18: 17 | L18: =K18*7+1 -> 120 | M18: 自选奇迹遗物·羽I | N18: =IF($P$1="是",IF(K18<$P$2,M18,IF(K18=$P$2,M19,IF(K18=$P$2+1,M21,M18)))) -> 原初宝石/贤者之石 | X18: 已有原初 | Y18: 目标档位 | Z18: 原初之星 | AA18: 还需分数 | AD18: 17 | AE18: 40 | AF18: =AF17+AE18 -> 360 | AG18: 副本掉落装备升华率 | AH18: 0.03 | AI18: =COUNTIF(AG$1:AG18,AG18)*AH18 -> 0.15 | AU18: 16 | AV18: 400 | AW18: 16 | AX18: 400 | AY18: 16 | AZ18: 400 | BR18: 素材秘境 | BS18: 每1个道具 | BZ18: 177 | CA18: =CA17+260 -> 30160 | CB18: =CA18*2 -> 60320 | CC18: =CA18*$BT$5+CB18*$BS$2 -> 361.92 | CD18: =CC18/14*13 -> 336.06857 | CE18: =(CA18/$BS$14*5+CB18/$BS$13*5)/14*13 -> 64.045267 | CG18: 177 | CH18: =CH17+195 -> 22305 | CI18: 0 | CJ18: =CH18*$BT$6+CI18*$BS$2 -> 178.44 | CK18: =CJ18/5*13 -> 463.944 | CL18: =(CH18/$BS$15*5+CI18/$BS$13*5)/5*13 -> 96.655 | CU18: 177 | CV18: 234150 | CW18: 0 | CX18: =CV18*$BT$8+CW18*$BS$2 -> 468.3 | CY18: =CX18/6*13 -> 1014.65 | DD18: 第2页 | DE18: =SUM($DH$30*2.5,$DM$30*2.5,$DR$30*0.5,$DW$30*3.125) -> 10800 | DF18: =10000*($DI$30*DT$3*2.5+$DN$30*DT$4*2.5+$DS$30*DT$5*0.5+$DX$30*DT$6*3.125) -> 484294.35 | DG18: 2448 | DJ18: 第2页 | DK18: =DG18/16*DO$2/((DE18*DT$1+DF18*DT$1)*DR$2/10000) -> 166.14624 | DM18: 防御 | DN18: =属性晨星性价比!I3 -> 11.3 | DO18: =属性晨星性价比!I8 -> 0.49 | DP18: =DN18*(1+DO18) -> 16.837 | EC18: 当前重置后幻兽面板 | ED18: 攻击力 | EE18: =幻兽同调计算器!C3 -> 5.18 | EF18: =EE18*2.5 -> 12.95 | EH18: 面板 | EI18: 攻击力 | EJ18: =EE18/$EE$16*$EJ$16/$ED$17*$EI$17 -> 4.2563603 | EK18: =EJ18*2.5 -> 10.640901 | FB18: 16 | FC18: 2040 | FD18: =SUM($FC$3:FC18) -> 25320 | FF18: 朵菈最终等级 | FH18: {=INDEX(FB3:FB101,MATCH(_xlfn.MAXIFS(FD3:FD101,FB3:FB101,FI15),FD17:FD18,0))} -> #N/A | FN18: 1w战力价格 | FO18: =10000/FO17*$FP$4 -> 65.070232 | FP18: =10000/FP17*$FP$4 -> 325.35116 | FQ18: =10000/FQ17*$FP$4 -> 650.70232 | FR18: =10000/FR17*$FP$4 -> 976.05348 | FS18: =10000/FS17*$FP$4 -> 1301.4046 | FT18: =10000/FT17*$FP$4 -> 1626.7558 | FU18: =10000/FU17*$FP$4 -> 195.2107
A19: 8 | B19: =秘宝大作战!D10-秘宝大作战!H10 -> -11520 | C19: =IF(B19<0,-B19,0) -> 11520 | D19: =IF(C19>0,A19*2*60,0) -> 960 | E19: =IF(C19>0,A19*2*300,0) -> 4800 | F19: =IF(C19-D19-E19>0,C19-D19-E19,0) -> 5760 | J19: =K19*2250-IF(K19<$R$1,0,$R$2)+IF($P$1="是",IF(K19<$P$2,0,1000),0) -> 41350 | K19: 18 | L19: =K19*7+1 -> 127 | M19: 幸运神像/黄金圣木 | N19: =IF($P$1="是",IF(K19<$P$2,M19,IF(K19=$P$2,M20,IF(K19=$P$2+1,M22,M19)))) -> 幸运神像/黄金圣木 | X19: 0 | Y19: =泽国星象合约计算器!H2 -> 200 | Z19: =FLOOR(AA17/AA4,1)+AB4 -> 128 | AA19: =(Y19-AB4-X19)*AA4-AA17 -> 7197 | AD19: 18 | AE19: 40 | AF19: =AF18+AE19 -> 400 | AG19: 宝石获取率 | AH19: 0.05 | AI19: =COUNTIF(AG$1:AG19,AG19)*AH19 -> 0.25 | AK19: 晨星售卖计算器 | AU19: 17 | AV19: 450 | AW19: 17 | AX19: 450 | AY19: 17 | AZ19: 450 | BR19: 金币 | BS19: =1920000000/100000 -> 19200 | BZ19: 178 | CA19: =CA18+260 -> 30420 | CB19: =CA19*2 -> 60840 | CC19: =CA19*$BT$5+CB19*$BS$2 -> 365.04 | CD19: =CC19/14*13 -> 338.96571 | CE19: =(CA19/$BS$14*5+CB19/$BS$13*5)/14*13 -> 64.597381 | CG19: 178 | CH19: =CH18+190 -> 22495 | CI19: 0 | CJ19: =CH19*$BT$6+CI19*$BS$2 -> 179.96 | CK19: =CJ19/5*13 -> 467.896 | CL19: =(CH19/$BS$15*5+CI19/$BS$13*5)/5*13 -> 97.478333 | CU19: 178 | CV19: 237700 | CW19: 0 | CX19: =CV19*$BT$8+CW19*$BS$2 -> 475.4 | CY19: =CX19/6*13 -> 1030.0333 | DD19: 第3页 | DE19: =SUM($DH$31*2.5,$DM$31*2.5,$DR$31*0.5,$DW$31*3.125) -> 12870 | DF19: =10000*($DI$31*DT$3*2.5+$DN$31*DT$4*2.5+$DS$31*DT$5*0.5+$DX$31*DT$6*3.125) -> 484415.32 | DG19: 3536 | DJ19: 第3页 | DK19: =DG19/16*DO$2/((DE19*DT$1+DF19*DT$1)*DR$2/10000) -> 238.93165 | DM19: 生命 | DN19: =属性晨星性价比!I4 -> 56.7 | DO19: =属性晨星性价比!I9 -> 0.48 | DP19: =DN19*(1+DO19) -> 83.916 | ED19: 防御力 | EE19: =幻兽同调计算器!C4 -> 5.18 | EF19: =EE19*2.5 -> 12.95 | EI19: 防御力 | EJ19: =EE19/$EE$16*$EJ$16/$ED$17*$EI$17 -> 4.2563603 | EK19: =EJ19*2.5 -> 10.640901 | FB19: 17 | FC19: 2100 | FD19: =SUM($FC$3:FC19) -> 27420 | FN19: 综合每碎片战力 | FO19: =(SUM(FO16:FU16)/SUM(FO15:FU15)) -> 475.75758
A20: 9 | B20: =秘宝大作战!D11-秘宝大作战!H11 -> -14910 | C20: =IF(B20<0,-B20,0) -> 14910 | D20: =IF(C20>0,A20*2*60,0) -> 1080 | E20: =IF(C20>0,A20*2*300,0) -> 5400 | F20: =IF(C20-D20-E20>0,C20-D20-E20,0) -> 8430 | J20: =K20*2250-IF(K20<$R$1,0,$R$2)+IF($P$1="是",IF(K20<$P$2,0,1000),0) -> 43600 | K20: 19 | L20: =K20*7+1 -> 134 | M20: 5阶技能碎片*180 | N20: =IF($P$1="是",IF(K20<$P$2,M20,IF(K20=$P$2,M21,IF(K20=$P$2+1,M23,M20)))) -> 5阶技能碎片*180 | AD20: 19 | AE20: 40 | AF20: =AF19+AE20 -> 440 | AG20: 副本评价奖励翻倍概率 | AH20: 0.02 | AI20: =COUNTIF(AG$1:AG20,AG20)*AH20 -> 0.1 | AL20: 原初 | AM20: 女神像 | AO20: 原初 | AP20: 翻倍率 | AQ20: 女神像 | AR20: 翻倍率 | AU20: 18 | AV20: 500 | AW20: 18 | AX20: 500 | AY20: 18 | AZ20: 500 | BR20: 粗练石 | BS20: =180000000/100000 -> 1800 | BZ20: 179 | CA20: =CA19+260 -> 30680 | CB20: =CA20*2 -> 61360 | CC20: =CA20*$BT$5+CB20*$BS$2 -> 368.16 | CD20: =CC20/14*13 -> 341.86286 | CE20: =(CA20/$BS$14*5+CB20/$BS$13*5)/14*13 -> 65.149496 | CG20: 179 | CH20: =CH19+195 -> 22690 | CI20: 0 | CJ20: =CH20*$BT$6+CI20*$BS$2 -> 181.52 | CK20: =CJ20/5*13 -> 471.952 | CL20: =(CH20/$BS$15*5+CI20/$BS$13*5)/5*13 -> 98.323333 | CU20: 179 | CV20: 241250 | CW20: 0 | CX20: =CV20*$BT$8+CW20*$BS$2 -> 482.5 | CY20: =CX20/6*13 -> 1045.4167 | DD20: 第4页 | DE20: =SUM($DH$32*2.5,$DM$32*2.5,$DR$32*0.5,$DW$32*3.125) -> 15060 | DF20: =10000*($DI$32*DT$3*2.5+$DN$32*DT$4*2.5+$DS$32*DT$5*0.5+$DX$32*DT$6*3.125) -> 484354.84 | DG20: 4080 | DJ20: 第4页 | DK20: =DG20/16*DO$2/((DE20*DT$1+DF20*DT$1)*DR$2/10000) -> 274.51482 | DM20: 速度 | DN20: =属性晨星性价比!I5 -> 9.08 | DO20: =属性晨星性价比!I10 -> 0.52 | DP20: =DN20*(1+DO20) -> 13.8016 | ED20: 生命值 | EE20: =幻兽同调计算器!C5 -> 25.9 | EF20: =EE20*0.5 -> 12.95 | EI20: 生命值 | EJ20: =EE20/$EE$16*$EJ$16/$ED$17*$EI$17 -> 21.281801 | EK20: =EJ20*0.5 -> 10.640901 | FB20: 18 | FC20: 2160 | FD20: =SUM($FC$3:FC20) -> 29580
A21: 10 | B21: =秘宝大作战!D12-秘宝大作战!H12 -> -17250 | C21: =IF(B21<0,-B21,0) -> 17250 | D21: =IF(C21>0,A21*2*60,0) -> 1200 | E21: =IF(C21>0,A21*2*300,0) -> 6000 | F21: =IF(C21-D21-E21>0,C21-D21-E21,0) -> 10050 | J21: =K21*2250-IF(K21<$R$1,0,$R$2)+IF($P$1="是",IF(K21<$P$2,0,1000),0) -> 45850 | K21: 20 | L21: =K21*7+1 -> 141 | M21: 原初宝石/贤者之石 | N21: =IF($P$1="是",IF(K21<$P$2,M21,IF(K21=$P$2,M22,IF(K21=$P$2+1,M24,M21)))) -> 原初宝石/贤者之石 | V21: 龙国计算 | AD21: 20 | AE21: 40 | AF21: =AF20+AE21 -> 480 | AG21: 经验获取加成 | AH21: 0.02 | AI21: =COUNTIF(AG$1:AG21,AG21)*AH21 -> 0.1 | AL21: =副本晨星收益计算器!C1 -> 3300 | AM21: =副本晨星收益计算器!F1 -> 2星架子上 | AO21: =AF4 -> 30 | AP21: =AI4 -> 0.02 | AQ21: 0星未放架子 | AR21: 0.1 | AU21: 19 | AV21: 500 | AW21: 19 | AX21: 500 | AY21: 19 | AZ21: 500 | BR21: 历战精华 | BS21: =268000000/100000 -> 2680 | BZ21: 180 | CA21: =CA20+260 -> 30940 | CB21: =CA21*2 -> 61880 | CC21: =CA21*$BT$5+CB21*$BS$2 -> 371.28 | CD21: =CC21/14*13 -> 344.76 | CE21: =(CA21/$BS$14*5+CB21/$BS$13*5)/14*13 -> 65.70161 | CG21: 180 | CH21: =CH20+190 -> 22880 | CI21: 0 | CJ21: =CH21*$BT$6+CI21*$BS$2 -> 183.04 | CK21: =CJ21/5*13 -> 475.904 | CL21: =(CH21/$BS$15*5+CI21/$BS$13*5)/5*13 -> 99.146667 | CU21: 180 | CV21: 244800 | CW21: 0 | CX21: =CV21*$BT$8+CW21*$BS$2 -> 489.6 | CY21: =CX21/6*13 -> 1060.8 | DD21: 第5页 | DE21: =SUM($DH$33*2.5,$DM$33*2.5,$DR$33*0.5,$DW$33*3.125) -> 15060 | DF21: =10000*($DI$33*DT$3*2.5+$DN$33*DT$4*2.5+$DS$33*DT$5*0.5+$DX$33*DT$6*3.125) -> 484354.84 | DG21: 4692 | DJ21: 第5页 | DK21: =DG21/16*DO$2/((DE21*DT$1+DF21*DT$1)*DR$2/10000) -> 315.69204 | ED21: 速度 | EE21: =幻兽同调计算器!C6 -> 4.14 | EF21: =EE21*3.125 -> 12.9375 | EI21: 速度 | EJ21: =EE21/$EE$16*$EJ$16/$ED$17*$EI$17 -> 3.4018015 | EK21: =EJ21*3.125 -> 10.63063 | FB21: 19 | FC21: 2220 | FD21: =SUM($FC$3:FC21) -> 31800 | FM21: 每抽收益 | FN21: =(FN2+FO2)*FN4*FO14+(FN3+FO3)*FN5*FO19 -> 1478.0751
